Workbook
Name ListaExercicios: 'Exercícios'!$A$6:$A$1000

Sheet Hoje
A2: Projeto Breno: registro rápido
A3: Use o menu Projeto. Salve o que souber; informações faltantes não impedem retomar o acompanhamento.
A4: Ação rápida | B4: —
A5: Data | B5: =TODAY() | D5: Status | E5: Planilha 4.0: objetivo, meta e ficha em vigor vêm das abas Objetivos, Metas e Fichas.
A7: Peso kg | D7: Sono h | G7: Passos | J7: Cardio min
A9: Registrou tudo? | B9: Não | D9: Muay Thai? | E9: Não | G9: Cintura cm | J9: Fome 1–5
A11: Cansaço 1–5 | D11: Observações
A14: Favorita | D14: Porções | E14: 1 | G14: Refeição | H14: Café da manhã
A16: Alimento | D16: Quantidade | G16: Medição | H16: Estimada | J16: Unidade →
A17: Escolha a unidade: 2 un de ovo ≠ 2 g. Conversões caseiras são estimadas.
A18: Copiar da data | D18: Refeição ou Todas | E18: Todas
A20: Refeição sem cálculo
A23: Sessão | D23: Fase | E23: Regular | G23: Ficha carregada
A24: Carga: siga o critério do cadastro de Exercícios. Preparação em cinza; work sets em verde.
A26: Exercício | B26: Aquec. kg | C26: Aquec. reps | D26: Feeder kg | E26: Feeder reps | F26: Work 1 kg | G26: Work 1 reps | H26: Work 2 kg | I26: Work 2 reps | J26: RIR work 2 | K26: Dor 0–10 | L26: Observação | M26: RIR work 1
A39: RIR = repetições em reserva. Informe para cada work set; 0 é um registro válido.
A40: Feeder: 6 reps longe da falha. Trabalho: 2×6–10, 0–1 RIR. Apenas work sets entram nos indicadores.
A42: Meta × realizado do dia
A43: Indicador | B43: Realizado | C43: Meta | D43: Comparação | E43: Status
A44: kcal | B44: =IF(COUNTIF('Alimentação'!$A:$A,$B$5)=0,"",SUMIFS('Alimentação'!$F:$F,'Alimentação'!$A:$A,$B$5)) | C44: =IF(COUNTIFS('Diário'!$A:$A,$B$5,'Diário'!$M:$M,">0")=0,"",SUMIFS('Diário'!$M:$M,'Diário'!$A:$A,$B$5)) | D44: =IF(NOT(ISNUMBER(B44)),"Sem registro",TEXT(B44,"0")&" / "&IF(ISNUMBER(C44),TEXT(C44,"0"),"meta pendente")) | E44: =IF(COUNTIF('Alimentação'!$A$6:$A1000,$B$5)=0,"Sem registro",IF(COUNTIFS('Diário'!$A$6:$A1000,$B$5,'Diário'!$G$6:$G1000,"Sim")=0,"Parcial — em andamento",IF(SUMIFS('Diário'!$AG$6:$AG1000,'Diário'!$A$6:$A1000,$B$5)>0,"Completo — cálculo parcial",IF(OR(NOT(ISNUMBER(B44)),NOT(ISNUMBER(C44))),"Pendente",IF(ABS(B44/C44-1)<=SUMIFS('Diário'!$T:$T,'Diário'!$A:$A,$B$5),"Na faixa",IF(ABS(B44/C44-1)<=0.2,"Próximo","Distante"))))))
A45: Proteína g | B45: =IF(COUNTIF('Alimentação'!$A:$A,$B$5)=0,"",SUMIFS('Alimentação'!$G:$G,'Alimentação'!$A:$A,$B$5)) | C45: =IF(COUNTIFS('Diário'!$A:$A,$B$5,'Diário'!$N:$N,">0")=0,"",SUMIFS('Diário'!$N:$N,'Diário'!$A:$A,$B$5)) | D45: =IF(NOT(ISNUMBER(B45)),"Sem registro",TEXT(B45,"0")&" / "&IF(ISNUMBER(C45),TEXT(C45,"0"),"meta pendente")) | E45: =IF(COUNTIF('Alimentação'!$A$6:$A1000,$B$5)=0,"Sem registro",IF(COUNTIFS('Diário'!$A$6:$A1000,$B$5,'Diário'!$G$6:$G1000,"Sim")=0,"Parcial — em andamento",IF(SUMIFS('Diário'!$AG$6:$AG1000,'Diário'!$A$6:$A1000,$B$5)>0,"Completo — cálculo parcial",IF(OR(NOT(ISNUMBER(B45)),NOT(ISNUMBER(C45))),"Pendente",IF(AND(B45>=SUMIFS('Diário'!$R:$R,'Diário'!$A:$A,$B$5),B45<=SUMIFS('Diário'!$S:$S,'Diário'!$A:$A,$B$5)),"Na faixa",IF(ABS(B45/C45-1)<=0.2,"Próximo","Distante"))))))
A46: Gordura g | B46: =IF(COUNTIF('Alimentação'!$A:$A,$B$5)=0,"",SUMIFS('Alimentação'!$I:$I,'Alimentação'!$A:$A,$B$5)) | C46: =IF(COUNTIFS('Diário'!$A:$A,$B$5,'Diário'!$O:$O,">0")=0,"",SUMIFS('Diário'!$O:$O,'Diário'!$A:$A,$B$5)) | D46: =IF(NOT(ISNUMBER(B46)),"Sem registro",TEXT(B46,"0")&" / "&IF(ISNUMBER(C46),TEXT(C46,"0"),"meta pendente")) | E46: =IF(COUNTIF('Alimentação'!$A$6:$A1000,$B$5)=0,"Sem registro",IF(COUNTIFS('Diário'!$A$6:$A1000,$B$5,'Diário'!$G$6:$G1000,"Sim")=0,"Parcial — em andamento",IF(SUMIFS('Diário'!$AG$6:$AG1000,'Diário'!$A$6:$A1000,$B$5)>0,"Completo — cálculo parcial",IF(OR(NOT(ISNUMBER(B46)),NOT(ISNUMBER(C46))),"Pendente",IF(ABS(B46/C46-1)<=SUMIFS('Diário'!$U:$U,'Diário'!$A:$A,$B$5),"Na faixa",IF(ABS(B46/C46-1)<=0.2,"Próximo","Distante"))))))
A48: Configuração e revisões
A50: Upper → Lower → Full Body. Organize os dias junto ao Muay Thai.
A51: Menu Projeto: carregar → registrar → salvar parcial ou concluir. Retome registros sem preencher dias atrasados.

Sheet Painel
A2: Projeto Breno: decisões da semana
A5: Semana iniciada em
A7: Peso médio kg
A8: Mudança vs semana anterior kg
A9: Cintura cm
A10: kcal — dias completos
A11: Proteína média g
A12: Gordura média g
A13: Dias completos com cálculo
A14: Aderência calórica
A15: Aderência proteína
A16: Treinos realizados
... A28: Semana parcial
A30: Metas históricas | B30: Aderência usa a meta gravada em cada dia.
A32: Faixas usadas | B32: kcal ±5%; gordura ±15%; proteína pela faixa individual.
A34: Próxima ação | B34: Revisar tolerância à musculação junto do Muay Thai.
A36: Cobertura alimentar
A38: Itens sem cálculo

Sheet Progressão
A2: Progressão por exercício
A3: Gerado pelo script a partir do Registro de treino. Só work sets contam.
A5: Exercício | B5: Grupo | E5: Último work | F5: RIR | G5: Tendência | H5: Sugestão | I5: Ficha

Sheet Config
A2: Configuração
A3: Perfil, rotina e limites da análise. Edite só a coluna Valor. Objetivo, meta e ficha atuais vêm das abas de histórico.
A5: Chave | B5: Parâmetro | C5: Valor | D5: Unidade | E5: Descrição
B6: Perfil
A7: client.name | B7: Nome | C7: Breno | E7: Nome exibido nos títulos e no Painel.
A8: client.sex | B8: Sexo (TMB) | C8: M | D8: M/F | E8: Usado só na equação de TMB (Mifflin-St Jeor).
A9: client.birthDate | B9: Data de nascimento | D9: data | E9: Se preenchida, a idade é calculada na data de cada meta.
A10: client.age | B10: Idade | C10: 24 | D10: anos | E10: Usada quando a data de nascimento não foi informada.
A11: client.heightCm | B11: Altura | C11: 179 | D11: cm | E11: Altura em centímetros.
A12: client.startWeightKg | B12: Peso inicial | C12: 67 | D12: kg | E12: Peso no início do acompanhamento (referência, não medição datada).
A13: client.startDate | B13: Início do acompanhamento | C13: 46286 | D13: data | E13: Data do primeiro registro.
A14: client.reviewer | B14: Revisor | C14: Luan | E14: Quem revisa metas, fichas e fases.
A15: client.notes | B15: Observações do perfil | C15: Saúde: não informado (relato, não avaliação clínica). Tabagismo: não informado. Rotina: pouca caminhada. Creatina: uso não confirmado. | E15: Saúde, suplementos, rotina e outros fatos relatados (não é avaliação clínica).
B16: Rotina
A17: routine.strengthPerWeek | B17: Musculação | C17: 3 | D17: sessões/semana | E17: Treinos de musculação planejados por semana.
A18: routine.cardioPerWeek | B18: Cardio | C18: 0 | D18: sessões/semana | E18: Sessões de cardio planejadas por semana.
A19: routine.activities | B19: Atividades | C19: Muay Thai | E19: Outras atividades (ex.: luta, corrida).
A20: routine.activitiesPerWeek | B20: Atividades por semana | C20: 2 | D20: sessões/semana | E20: Sessões das outras atividades por semana.
A21: routine.sessionRotation | B21: Rotação de sessões | C21: Upper, Lower, Full Body | D21: lista | E21: Sessões da ficha em ordem, separadas por vírgula.
A22: routine.rotationMode | B22: Modo da rotação | C22: continuous | E22: continuous = próxima sessão após a última concluída; weekly = recomeça toda semana.
B23: Energia
A24: energy.bmrMethod | B24: Método da TMB | C24: mifflin | E24: Equação usada para a taxa metabólica basal.
A25: energy.activityFactor | B25: Fator de atividade | C25: 1.55 | D25: × | E25: Multiplica a TMB para o gasto estimado. Estimativa: revisar.
B26: Análise
A27: analysis.weightTrendDays | B27: Dias da média de peso | C27: 7 | D27: dias | E27: Janela da média móvel de peso.
A28: analysis.minWeighInsPerWeek | B28: Pesagens mínimas | C28: 3 | D28: por semana | E28: Abaixo disso a tendência de peso é dados insuficientes.
A29: analysis.minCompleteFoodDays | B29: Dias completos mínimos | C29: 4 | D29: por semana | E29: Dias com alimentação completa para avaliar a dieta.
A30: analysis.kcalTolerance | B30: Tolerância kcal | C30: 0.05 | D30: fração | E30: Faixa aceita em torno da meta de kcal (0,05 = ±5%).
A31: analysis.fatTolerance | B31: Tolerância gordura | C31: 0.15 | D31: fração | E31: Faixa aceita em torno da meta de gordura.
A32: analysis.waistNoiseCm | B32: Ruído da cintura | C32: 0.5 | D32: cm | E32: Variações menores são tratadas como estáveis.
A33: analysis.weightNoisePctPerWeek | B33: Ruído do peso | C33: 0.25 | D33: %/semana | E33: Variações menores são tratadas como peso estável.
A34: analysis.sleepMinH | B34: Sono mínimo | C34: 7 | D34: h | E34: Média abaixo disso gera sinal de sono baixo.
A35: analysis.fatigueHigh | B35: Cansaço alto | C35: 4 | D35: 1–5 | E35: Média a partir disso gera sinal de fadiga alta.
A36: analysis.hungerHigh | B36: Fome alta | C36: 4 | D36: 1–5 | E36: Média a partir disso gera sinal de fome alta.
A37: analysis.painHigh | B37: Dor alta | C37: 4 | D37: 0–10 | E37: Máximo a partir disso gera sinal de dor alta.
A38: analysis.reviewEveryDays | B38: Intervalo de revisão | C38: 7 | D38: dias | E38: Próxima revisão sugerida após uma decisão.
A39: analysis.minWeeksForPhaseReview | B39: Semanas mínimas por fase | C39: 8 | D39: semanas | E39: Antes disso não se sugere revisar objetivo/fase por sucesso.
B40: Sistema
A41: system.schemaVersion | B41: Versão do esquema | C41: 4.0 | E41: Gravada pela migração/configuração inicial. Não editar.
A42: system.timezone | B42: Fuso horário | E42: Vazio = fuso do projeto do Apps Script.
...

Sheet Ficha de treino
A2: Ficha vigente
A3: Mostra a ficha em vigor. Edite como rascunho e use Salvar nova ficha para criar a próxima versão.
A5: Sessão | B5: Exercício | C5: Grupo principal | D5: Work sets adaptação | E5: Work sets regular | F5: Reps work mín. | G5: Reps work máx. | H5: RIR work adaptação máx. | I5: RIR work regular máx. | J5: Descanso s | K5: Alternativa | L5: Status do plano | M5: Tipos de série
A6: Upper | B6: Supino inclinado | C6: Peito | D6: 2 | E6: 2 | F6: 6 | G6: 10 | H6: 1 | I6: 1 | J6: 150 | K6: Supino inclinado máquina | L6: Confirmado por Luan | M6: 1 aquecimento + 1 feeder de 6 reps longe da falha + 2 work sets de 6–10 reps, 0–1 RIR.
A7: Upper | B7: Puxada aberta | C7: Costas | D7: 2 | E7: 2 | F7: 6 | G7: 10 | H7: 1 | I7: 1 | J7: 150 | L7: Confirmado por Luan | M7: 1 aquecimento + 1 feeder de 6 reps longe da falha + 2 work sets de 6–10 reps, 0–1 RIR.
A8: Upper | B8: Remada baixa com triângulo | C8: Costas | D8: 2 | E8: 2 | F8: 6 | G8: 10 | H8: 1 | I8: 1 | J8: 150 | L8: Confirmado por Luan | M8: 1 aquecimento + 1 feeder de 6 reps longe da falha + 2 work sets de 6–10 reps, 0–1 RIR.
A9: Upper | B9: Supino reto na máquina | C9: Peito | D9: 2 | E9: 2 | F9: 6 | G9: 10 | H9: 1 | I9: 1 | J9: 150 | L9: Confirmado por Luan | M9: 1 aquecimento + 1 feeder de 6 reps longe da falha + 2 work sets de 6–10 reps, 0–1 RIR.
A10: Upper | B10: Elevação lateral | C10: Ombros | D10: 2 | E10: 2 | F10: 6 | G10: 10 | H10: 1 | I10: 1 | J10: 120 | L10: Confirmado por Luan | M10: 1 aquecimento + 1 feeder de 6 reps longe da falha + 2 work sets de 6–10 reps, 0–1 RIR.
A11: Upper | B11: Crucifixo inverso | C11: Ombros | D11: 2 | E11: 2 | F11: 6 | G11: 10 | H11: 1 | I11: 1 | J11: 120 | K11: Peck deck reverso | L11: Confirmado por Luan | M11: 1 aquecimento + 1 feeder de 6 reps longe da falha + 2 work sets de 6–10 reps, 0–1 RIR.
A12: Upper | B12: Rosca Scott | C12: Bíceps | D12: 2 | E12: 2 | F12: 6 | G12: 10 | H12: 1 | I12: 1 | J12: 120 | L12: Confirmado por Luan | M12: 1 aquecimento + 1 feeder de 6 reps longe da falha + 2 work sets de 6–10 reps, 0–1 RIR.
A13: Upper | B13: Tríceps na corda | C13: Tríceps | D13: 2 | E13: 2 | F13: 6 | G13: 10 | H13: 1 | I13: 1 | J13: 120 | L13: Confirmado por Luan | M13: 1 aquecimento + 1 feeder de 6 reps longe da falha + 2 work sets de 6–10 reps, 0–1 RIR.
A14: Lower | B14: Agachamento orientado | C14: Quadríceps | D14: 2 | E14: 2 | F14: 6 | G14: 10 | H14: 1 | I14: 1 | J14: 150 | L14: Confirmado por Luan | M14: 1 aquecimento + 1 feeder de 6 reps longe da falha + 2 work sets de 6–10 reps, 0–1 RIR.
A15: Lower | B15: Leg press | C15: Quadríceps | D15: 2 | E15: 2 | F15: 6 | G15: 10 | H15: 1 | I15: 1 | J15: 150 | L15: Confirmado por Luan | M15: 1 aquecimento + 1 feeder de 6 reps longe da falha + 2 work sets de 6–10 reps, 0–1 RIR.
A16: Lower | B16: Stiff orientado | C16: Posteriores | D16: 2 | E16: 2 | F16: 6 | G16: 10 | H16: 1 | I16: 1 | J16: 150 | L16: Confirmado por Luan | M16: 1 aquecimento + 1 feeder de 6 reps longe da falha + 2 work sets de 6–10 reps, 0–1 RIR.
A17: Lower | B17: Mesa flexora | C17: Posteriores | D17: 2 | E17: 2 | F17: 6 | G17: 10 | H17: 1 | I17: 1 | J17: 150 | L17: Confirmado por Luan | M17: 1 aquecimento + 1 feeder de 6 reps longe da falha + 2 work sets de 6–10 reps, 0–1 RIR.
A18: Lower | B18: Panturrilha em pé | C18: Panturrilhas | D18: 2 | E18: 2 | F18: 6 | G18: 10 | H18: 1 | I18: 1 | J18: 120 | K18: Panturrilha sentado | L18: Confirmado por Luan | M18: 1 aquecimento + 1 feeder de 6 reps longe da falha + 2 work sets de 6–10 reps, 0–1 RIR.
A19: Lower | B19: Abdominal na polia | C19: Abdômen | D19: 2 | E19: 2 | F19: 6 | G19: 10 | H19: 1 | I19: 1 | J19: 120 | L19: Confirmado por Luan | M19: 1 aquecimento + 1 feeder de 6 reps longe da falha + 2 work sets de 6–10 reps, 0–1 RIR.
A20: Full Body | B20: Leg press | C20: Quadríceps | D20: 2 | E20: 2 | F20: 6 | G20: 10 | H20: 1 | I20: 1 | J20: 150 | L20: Confirmado por Luan | M20: 1 aquecimento + 1 feeder de 6 reps longe da falha + 2 work sets de 6–10 reps, 0–1 RIR.
A21: Full Body | B21: Supino inclinado com halteres | C21: Peito | D21: 2 | E21: 2 | F21: 6 | G21: 10 | H21: 1 | I21: 1 | J21: 150 | L21: Confirmado por Luan | M21: 1 aquecimento + 1 feeder de 6 reps longe da falha + 2 work sets de 6–10 reps, 0–1 RIR.
A22: Full Body | B22: Puxada aberta | C22: Costas | D22: 2 | E22: 2 | F22: 6 | G22: 10 | H22: 1 | I22: 1 | J22: 150 | L22: Confirmado por Luan | M22: 1 aquecimento + 1 feeder de 6 reps longe da falha + 2 work sets de 6–10 reps, 0–1 RIR.
A23: Full Body | B23: Remada com apoio | C23: Costas | D23: 2 | E23: 2 | F23: 6 | G23: 10 | H23: 1 | I23: 1 | J23: 150 | K23: Máquina disponível; confirmar execução com Luan | L23: Confirmado por Luan | M23: 1 aquecimento + 1 feeder de 6 reps longe da falha + 2 work sets de 6–10 reps, 0–1 RIR.
A24: Full Body | B24: Elevação lateral | C24: Ombros | D24: 2 | E24: 2 | F24: 6 | G24: 10 | H24: 1 | I24: 1 | J24: 120 | L24: Confirmado por Luan | M24: 1 aquecimento + 1 feeder de 6 reps longe da falha + 2 work sets de 6–10 reps, 0–1 RIR.
A25: Full Body | B25: Crucifixo inverso | C25: Ombros | D25: 2 | E25: 2 | F25: 6 | G25: 10 | H25: 1 | I25: 1 | J25: 120 | K25: Peck deck reverso | L25: Confirmado por Luan | M25: 1 aquecimento + 1 feeder de 6 reps longe da falha + 2 work sets de 6–10 reps, 0–1 RIR.
A26: Full Body | B26: Rosca alternada | C26: Bíceps | D26: 2 | E26: 2 | F26: 6 | G26: 10 | H26: 1 | I26: 1 | J26: 120 | L26: Confirmado por Luan | M26: 1 aquecimento + 1 feeder de 6 reps longe da falha + 2 work sets de 6–10 reps, 0–1 RIR.
A27: Full Body | B27: Tríceps na corda | C27: Tríceps | D27: 2 | E27: 2 | F27: 6 | G27: 10 | H27: 1 | I27: 1 | J27: 120 | L27: Confirmado por Luan | M27: 1 aquecimento + 1 feeder de 6 reps longe da falha + 2 work sets de 6–10 reps, 0–1 RIR.

Sheet Registro de treino
A2: Registro por exercício e sessão
A3: Aquecimento e feeder preservados; volume e progressão só com Work 1 + Work 2. Salvar parcial permite retomar.
A5: Data | B5: Sessão | C5: Exercício | D5: Equipamento / carga | E5: Aquecimento kg | F5: Aquecimento reps | G5: Feeder kg | H5: Feeder reps | I5: Work 1 kg | J5: Work 1 reps | K5: Work 2 kg | L5: Work 2 reps | M5: Work sets realizadas | N5: Volume work kg×reps | O5: RIR work 2 | P5: Dor 0–10 | Q5: Observação | R5: Ficha | S5: Work sets prescritas | T5: Reps work mín | U5: Reps work máx | V5: Fase | W5: ID sessão | X5: RIR work 1 | Y5: Estado sessão | Z5: Modelo de séries | AA5: Objetivo

Sheet Dieta base
A2: Dieta base com porções revisáveis
A3: Plano alimentar de referência. Os totais são a dieta planejada, não a ingestão realizada.
A5: Refeição | B5: Alimento | C5: Quantidade | D5: Unidade | E5: kcal | F5: Proteína g | G5: Carboidrato g | H5: Gordura g | I5: Fibra g | J5: Adaptação / observação
A6: Café da manhã | B6: Ovo inteiro cru | C6: 150 | D6: =VLOOKUP(B6,Alimentos!$A:$L,2,FALSE) | E6: =C6/VLOOKUP(B6,Alimentos!$A:$L,3,FALSE)*VLOOKUP(B6,Alimentos!$A:$L,4,FALSE) | F6: =C6/VLOOKUP(B6,Alimentos!$A:$L,3,FALSE)*VLOOKUP(B6,Alimentos!$A:$L,5,FALSE) | G6: =C6/VLOOKUP(B6,Alimentos!$A:$L,3,FALSE)*VLOOKUP(B6,Alimentos!$A:$L,6,FALSE) | H6: =C6/VLOOKUP(B6,Alimentos!$A:$L,3,FALSE)*VLOOKUP(B6,Alimentos!$A:$L,7,FALSE) | I6: =C6/VLOOKUP(B6,Alimentos!$A:$L,3,FALSE)*VLOOKUP(B6,Alimentos!$A:$L,8,FALSE) | J6: 3 ovos médios; pesar cru na balança sem casca
A7: Café da manhã | B7: Margarina (estimativa) | C7: 5 | D7: =VLOOKUP(B7,Alimentos!$A:$L,2,FALSE) | E7: =C7/VLOOKUP(B7,Alimentos!$A:$L,3,FALSE)*VLOOKUP(B7,Alimentos!$A:$L,4,FALSE) | F7: =C7/VLOOKUP(B7,Alimentos!$A:$L,3,FALSE)*VLOOKUP(B7,Alimentos!$A:$L,5,FALSE) | G7: =C7/VLOOKUP(B7,Alimentos!$A:$L,3,FALSE)*VLOOKUP(B7,Alimentos!$A:$L,6,FALSE) | H7: =C7/VLOOKUP(B7,Alimentos!$A:$L,3,FALSE)*VLOOKUP(B7,Alimentos!$A:$L,7,FALSE) | I7: =C7/VLOOKUP(B7,Alimentos!$A:$L,3,FALSE)*VLOOKUP(B7,Alimentos!$A:$L,8,FALSE) | J7: Gordura de preparo dos ovos na frigideira
A8: Café da manhã | B8: Pão integral | C8: 50 | D8: =VLOOKUP(B8,Alimentos!$A:$L,2,FALSE) | E8: =C8/VLOOKUP(B8,Alimentos!$A:$L,3,FALSE)*VLOOKUP(B8,Alimentos!$A:$L,4,FALSE) | F8: =C8/VLOOKUP(B8,Alimentos!$A:$L,3,FALSE)*VLOOKUP(B8,Alimentos!$A:$L,5,FALSE) | G8: =C8/VLOOKUP(B8,Alimentos!$A:$L,3,FALSE)*VLOOKUP(B8,Alimentos!$A:$L,6,FALSE) | H8: =C8/VLOOKUP(B8,Alimentos!$A:$L,3,FALSE)*VLOOKUP(B8,Alimentos!$A:$L,7,FALSE) | I8: =C8/VLOOKUP(B8,Alimentos!$A:$L,3,FALSE)*VLOOKUP(B8,Alimentos!$A:$L,8,FALSE) | J8: Cerca de 2 fatias
A9: Café da manhã | B9: Banana nanica | C9: 100 | D9: =VLOOKUP(B9,Alimentos!$A:$L,2,FALSE) | E9: =C9/VLOOKUP(B9,Alimentos!$A:$L,3,FALSE)*VLOOKUP(B9,Alimentos!$A:$L,4,FALSE) | F9: =C9/VLOOKUP(B9,Alimentos!$A:$L,3,FALSE)*VLOOKUP(B9,Alimentos!$A:$L,5,FALSE) | G9: =C9/VLOOKUP(B9,Alimentos!$A:$L,3,FALSE)*VLOOKUP(B9,Alimentos!$A:$L,6,FALSE) | H9: =C9/VLOOKUP(B9,Alimentos!$A:$L,3,FALSE)*VLOOKUP(B9,Alimentos!$A:$L,7,FALSE) | I9: =C9/VLOOKUP(B9,Alimentos!$A:$L,3,FALSE)*VLOOKUP(B9,Alimentos!$A:$L,8,FALSE)
A10: Café da manhã | B10: Queijo minas frescal | C10: 20 | D10: =VLOOKUP(B10,Alimentos!$A:$L,2,FALSE) | E10: =C10/VLOOKUP(B10,Alimentos!$A:$L,3,FALSE)*VLOOKUP(B10,Alimentos!$A:$L,4,FALSE) | F10: =C10/VLOOKUP(B10,Alimentos!$A:$L,3,FALSE)*VLOOKUP(B10,Alimentos!$A:$L,5,FALSE) | G10: =C10/VLOOKUP(B10,Alimentos!$A:$L,3,FALSE)*VLOOKUP(B10,Alimentos!$A:$L,6,FALSE) | H10: =C10/VLOOKUP(B10,Alimentos!$A:$L,3,FALSE)*VLOOKUP(B10,Alimentos!$A:$L,7,FALSE) | I10: =C10/VLOOKUP(B10,Alimentos!$A:$L,3,FALSE)*VLOOKUP(B10,Alimentos!$A:$L,8,FALSE)
A11: Café da manhã | B11: Leite integral (estimativa) | C11: 200 | D11: =VLOOKUP(B11,Alimentos!$A:$L,2,FALSE) | E11: =C11/VLOOKUP(B11,Alimentos!$A:$L,3,FALSE)*VLOOKUP(B11,Alimentos!$A:$L,4,FALSE) | F11: =C11/VLOOKUP(B11,Alimentos!$A:$L,3,FALSE)*VLOOKUP(B11,Alimentos!$A:$L,5,FALSE) | G11: =C11/VLOOKUP(B11,Alimentos!$A:$L,3,FALSE)*VLOOKUP(B11,Alimentos!$A:$L,6,FALSE) | H11: =C11/VLOOKUP(B11,Alimentos!$A:$L,3,FALSE)*VLOOKUP(B11,Alimentos!$A:$L,7,FALSE) | I11: =C11/VLOOKUP(B11,Alimentos!$A:$L,3,FALSE)*VLOOKUP(B11,Alimentos!$A:$L,8,FALSE)
A12: Almoço | B12: Arroz branco cozido | C12: 200 | D12: =VLOOKUP(B12,Alimentos!$A:$L,2,FALSE) | E12: =C12/VLOOKUP(B12,Alimentos!$A:$L,3,FALSE)*VLOOKUP(B12,Alimentos!$A:$L,4,FALSE) | F12: =C12/VLOOKUP(B12,Alimentos!$A:$L,3,FALSE)*VLOOKUP(B12,Alimentos!$A:$L,5,FALSE) | G12: =C12/VLOOKUP(B12,Alimentos!$A:$L,3,FALSE)*VLOOKUP(B12,Alimentos!$A:$L,6,FALSE) | H12: =C12/VLOOKUP(B12,Alimentos!$A:$L,3,FALSE)*VLOOKUP(B12,Alimentos!$A:$L,7,FALSE) | I12: =C12/VLOOKUP(B12,Alimentos!$A:$L,3,FALSE)*VLOOKUP(B12,Alimentos!$A:$L,8,FALSE) | J12: Porção ajustada para aproximar o total de 2.400 kcal
A13: Almoço | B13: Feijão carioca cozido | C13: 100 | D13: =VLOOKUP(B13,Alimentos!$A:$L,2,FALSE) | E13: =C13/VLOOKUP(B13,Alimentos!$A:$L,3,FALSE)*VLOOKUP(B13,Alimentos!$A:$L,4,FALSE) | F13: =C13/VLOOKUP(B13,Alimentos!$A:$L,3,FALSE)*VLOOKUP(B13,Alimentos!$A:$L,5,FALSE) | G13: =C13/VLOOKUP(B13,Alimentos!$A:$L,3,FALSE)*VLOOKUP(B13,Alimentos!$A:$L,6,FALSE) | H13: =C13/VLOOKUP(B13,Alimentos!$A:$L,3,FALSE)*VLOOKUP(B13,Alimentos!$A:$L,7,FALSE) | I13: =C13/VLOOKUP(B13,Alimentos!$A:$L,3,FALSE)*VLOOKUP(B13,Alimentos!$A:$L,8,FALSE)
A14: Almoço | B14: Peito de frango cozido | C14: 100 | D14: =VLOOKUP(B14,Alimentos!$A:$L,2,FALSE) | E14: =C14/VLOOKUP(B14,Alimentos!$A:$L,3,FALSE)*VLOOKUP(B14,Alimentos!$A:$L,4,FALSE) | F14: =C14/VLOOKUP(B14,Alimentos!$A:$L,3,FALSE)*VLOOKUP(B14,Alimentos!$A:$L,5,FALSE) | G14: =C14/VLOOKUP(B14,Alimentos!$A:$L,3,FALSE)*VLOOKUP(B14,Alimentos!$A:$L,6,FALSE) | H14: =C14/VLOOKUP(B14,Alimentos!$A:$L,3,FALSE)*VLOOKUP(B14,Alimentos!$A:$L,7,FALSE) | I14: =C14/VLOOKUP(B14,Alimentos!$A:$L,3,FALSE)*VLOOKUP(B14,Alimentos!$A:$L,8,FALSE) | J14: Ajustado de 130–150 g para evitar excesso na soma do dia
A15: Almoço | B15: Cenoura cozida | C15: 100 | D15: =VLOOKUP(B15,Alimentos!$A:$L,2,FALSE) | E15: =C15/VLOOKUP(B15,Alimentos!$A:$L,3,FALSE)*VLOOKUP(B15,Alimentos!$A:$L,4,FALSE) | F15: =C15/VLOOKUP(B15,Alimentos!$A:$L,3,FALSE)*VLOOKUP(B15,Alimentos!$A:$L,5,FALSE) | G15: =C15/VLOOKUP(B15,Alimentos!$A:$L,3,FALSE)*VLOOKUP(B15,Alimentos!$A:$L,6,FALSE) | H15: =C15/VLOOKUP(B15,Alimentos!$A:$L,3,FALSE)*VLOOKUP(B15,Alimentos!$A:$L,7,FALSE) | I15: =C15/VLOOKUP(B15,Alimentos!$A:$L,3,FALSE)*VLOOKUP(B15,Alimentos!$A:$L,8,FALSE) | J15: Exemplo de legumes
A16: Almoço | B16: Alface crua | C16: 50 | D16: =VLOOKUP(B16,Alimentos!$A:$L,2,FALSE) | E16: =C16/VLOOKUP(B16,Alimentos!$A:$L,3,FALSE)*VLOOKUP(B16,Alimentos!$A:$L,4,FALSE) | F16: =C16/VLOOKUP(B16,Alimentos!$A:$L,3,FALSE)*VLOOKUP(B16,Alimentos!$A:$L,5,FALSE) | G16: =C16/VLOOKUP(B16,Alimentos!$A:$L,3,FALSE)*VLOOKUP(B16,Alimentos!$A:$L,6,FALSE) | H16: =C16/VLOOKUP(B16,Alimentos!$A:$L,3,FALSE)*VLOOKUP(B16,Alimentos!$A:$L,7,FALSE) | I16: =C16/VLOOKUP(B16,Alimentos!$A:$L,3,FALSE)*VLOOKUP(B16,Alimentos!$A:$L,8,FALSE)
A17: Almoço | B17: Azeite | C17: 10 | D17: =VLOOKUP(B17,Alimentos!$A:$L,2,FALSE) | E17: =C17/VLOOKUP(B17,Alimentos!$A:$L,3,FALSE)*VLOOKUP(B17,Alimentos!$A:$L,4,FALSE) | F17: =C17/VLOOKUP(B17,Alimentos!$A:$L,3,FALSE)*VLOOKUP(B17,Alimentos!$A:$L,5,FALSE) | G17: =C17/VLOOKUP(B17,Alimentos!$A:$L,3,FALSE)*VLOOKUP(B17,Alimentos!$A:$L,6,FALSE) | H17: =C17/VLOOKUP(B17,Alimentos!$A:$L,3,FALSE)*VLOOKUP(B17,Alimentos!$A:$L,7,FALSE) | I17: =C17/VLOOKUP(B17,Alimentos!$A:$L,3,FALSE)*VLOOKUP(B17,Alimentos!$A:$L,8,FALSE) | J17: Gordura estimada do preparo; não duplicar
A18: Almoço | B18: Laranja pera | C18: 150 | D18: =VLOOKUP(B18,Alimentos!$A:$L,2,FALSE) | E18: =C18/VLOOKUP(B18,Alimentos!$A:$L,3,FALSE)*VLOOKUP(B18,Alimentos!$A:$L,4,FALSE) | F18: =C18/VLOOKUP(B18,Alimentos!$A:$L,3,FALSE)*VLOOKUP(B18,Alimentos!$A:$L,5,FALSE) | G18: =C18/VLOOKUP(B18,Alimentos!$A:$L,3,FALSE)*VLOOKUP(B18,Alimentos!$A:$L,6,FALSE) | H18: =C18/VLOOKUP(B18,Alimentos!$A:$L,3,FALSE)*VLOOKUP(B18,Alimentos!$A:$L,7,FALSE) | I18: =C18/VLOOKUP(B18,Alimentos!$A:$L,3,FALSE)*VLOOKUP(B18,Alimentos!$A:$L,8,FALSE)
A19: Jantar | B19: Arroz branco cozido | C19: 200 | D19: =VLOOKUP(B19,Alimentos!$A:$L,2,FALSE) | E19: =C19/VLOOKUP(B19,Alimentos!$A:$L,3,FALSE)*VLOOKUP(B19,Alimentos!$A:$L,4,FALSE) | F19: =C19/VLOOKUP(B19,Alimentos!$A:$L,3,FALSE)*VLOOKUP(B19,Alimentos!$A:$L,5,FALSE) | G19: =C19/VLOOKUP(B19,Alimentos!$A:$L,3,FALSE)*VLOOKUP(B19,Alimentos!$A:$L,6,FALSE) | H19: =C19/VLOOKUP(B19,Alimentos!$A:$L,3,FALSE)*VLOOKUP(B19,Alimentos!$A:$L,7,FALSE) | I19: =C19/VLOOKUP(B19,Alimentos!$A:$L,3,FALSE)*VLOOKUP(B19,Alimentos!$A:$L,8,FALSE) | J19: Porção ajustada para aproximar o total de 2.400 kcal
A20: Jantar | B20: Feijão carioca cozido | C20: 100 | D20: =VLOOKUP(B20,Alimentos!$A:$L,2,FALSE) | E20: =C20/VLOOKUP(B20,Alimentos!$A:$L,3,FALSE)*VLOOKUP(B20,Alimentos!$A:$L,4,FALSE) | F20: =C20/VLOOKUP(B20,Alimentos!$A:$L,3,FALSE)*VLOOKUP(B20,Alimentos!$A:$L,5,FALSE) | G20: =C20/VLOOKUP(B20,Alimentos!$A:$L,3,FALSE)*VLOOKUP(B20,Alimentos!$A:$L,6,FALSE) | H20: =C20/VLOOKUP(B20,Alimentos!$A:$L,3,FALSE)*VLOOKUP(B20,Alimentos!$A:$L,7,FALSE) | I20: =C20/VLOOKUP(B20,Alimentos!$A:$L,3,FALSE)*VLOOKUP(B20,Alimentos!$A:$L,8,FALSE)
A21: Jantar | B21: Peito de frango cozido | C21: 100 | D21: =VLOOKUP(B21,Alimentos!$A:$L,2,FALSE) | E21: =C21/VLOOKUP(B21,Alimentos!$A:$L,3,FALSE)*VLOOKUP(B21,Alimentos!$A:$L,4,FALSE) | F21: =C21/VLOOKUP(B21,Alimentos!$A:$L,3,FALSE)*VLOOKUP(B21,Alimentos!$A:$L,5,FALSE) | G21: =C21/VLOOKUP(B21,Alimentos!$A:$L,3,FALSE)*VLOOKUP(B21,Alimentos!$A:$L,6,FALSE) | H21: =C21/VLOOKUP(B21,Alimentos!$A:$L,3,FALSE)*VLOOKUP(B21,Alimentos!$A:$L,7,FALSE) | I21: =C21/VLOOKUP(B21,Alimentos!$A:$L,3,FALSE)*VLOOKUP(B21,Alimentos!$A:$L,8,FALSE) | J21: Ajustado de 130–150 g para evitar excesso na soma do dia
A22: Jantar | B22: Cenoura cozida | C22: 100 | D22: =VLOOKUP(B22,Alimentos!$A:$L,2,FALSE) | E22: =C22/VLOOKUP(B22,Alimentos!$A:$L,3,FALSE)*VLOOKUP(B22,Alimentos!$A:$L,4,FALSE) | F22: =C22/VLOOKUP(B22,Alimentos!$A:$L,3,FALSE)*VLOOKUP(B22,Alimentos!$A:$L,5,FALSE) | G22: =C22/VLOOKUP(B22,Alimentos!$A:$L,3,FALSE)*VLOOKUP(B22,Alimentos!$A:$L,6,FALSE) | H22: =C22/VLOOKUP(B22,Alimentos!$A:$L,3,FALSE)*VLOOKUP(B22,Alimentos!$A:$L,7,FALSE) | I22: =C22/VLOOKUP(B22,Alimentos!$A:$L,3,FALSE)*VLOOKUP(B22,Alimentos!$A:$L,8,FALSE) | J22: Exemplo de legumes
A23: Jantar | B23: Alface crua | C23: 50 | D23: =VLOOKUP(B23,Alimentos!$A:$L,2,FALSE) | E23: =C23/VLOOKUP(B23,Alimentos!$A:$L,3,FALSE)*VLOOKUP(B23,Alimentos!$A:$L,4,FALSE) | F23: =C23/VLOOKUP(B23,Alimentos!$A:$L,3,FALSE)*VLOOKUP(B23,Alimentos!$A:$L,5,FALSE) | G23: =C23/VLOOKUP(B23,Alimentos!$A:$L,3,FALSE)*VLOOKUP(B23,Alimentos!$A:$L,6,FALSE) | H23: =C23/VLOOKUP(B23,Alimentos!$A:$L,3,FALSE)*VLOOKUP(B23,Alimentos!$A:$L,7,FALSE) | I23: =C23/VLOOKUP(B23,Alimentos!$A:$L,3,FALSE)*VLOOKUP(B23,Alimentos!$A:$L,8,FALSE)
A24: Jantar | B24: Azeite | C24: 10 | D24: =VLOOKUP(B24,Alimentos!$A:$L,2,FALSE) | E24: =C24/VLOOKUP(B24,Alimentos!$A:$L,3,FALSE)*VLOOKUP(B24,Alimentos!$A:$L,4,FALSE) | F24: =C24/VLOOKUP(B24,Alimentos!$A:$L,3,FALSE)*VLOOKUP(B24,Alimentos!$A:$L,5,FALSE) | G24: =C24/VLOOKUP(B24,Alimentos!$A:$L,3,FALSE)*VLOOKUP(B24,Alimentos!$A:$L,6,FALSE) | H24: =C24/VLOOKUP(B24,Alimentos!$A:$L,3,FALSE)*VLOOKUP(B24,Alimentos!$A:$L,7,FALSE) | I24: =C24/VLOOKUP(B24,Alimentos!$A:$L,3,FALSE)*VLOOKUP(B24,Alimentos!$A:$L,8,FALSE) | J24: Gordura estimada do preparo; não duplicar
A25: Lanche | B25: Whey (rótulo a conferir) | C25: 10 | D25: =VLOOKUP(B25,Alimentos!$A:$L,2,FALSE) | E25: =C25/VLOOKUP(B25,Alimentos!$A:$L,3,FALSE)*VLOOKUP(B25,Alimentos!$A:$L,4,FALSE) | F25: =C25/VLOOKUP(B25,Alimentos!$A:$L,3,FALSE)*VLOOKUP(B25,Alimentos!$A:$L,5,FALSE) | G25: =C25/VLOOKUP(B25,Alimentos!$A:$L,3,FALSE)*VLOOKUP(B25,Alimentos!$A:$L,6,FALSE) | H25: =C25/VLOOKUP(B25,Alimentos!$A:$L,3,FALSE)*VLOOKUP(B25,Alimentos!$A:$L,7,FALSE) | I25: =C25/VLOOKUP(B25,Alimentos!$A:$L,3,FALSE)*VLOOKUP(B25,Alimentos!$A:$L,8,FALSE) | J25: 10 g de pó na proposta atual; conferir rótulo.
A26: Lanche | B26: Leite integral (estimativa) | C26: 200 | D26: =VLOOKUP(B26,Alimentos!$A:$L,2,FALSE) | E26: =C26/VLOOKUP(B26,Alimentos!$A:$L,3,FALSE)*VLOOKUP(B26,Alimentos!$A:$L,4,FALSE) | F26: =C26/VLOOKUP(B26,Alimentos!$A:$L,3,FALSE)*VLOOKUP(B26,Alimentos!$A:$L,5,FALSE) | G26: =C26/VLOOKUP(B26,Alimentos!$A:$L,3,FALSE)*VLOOKUP(B26,Alimentos!$A:$L,6,FALSE) | H26: =C26/VLOOKUP(B26,Alimentos!$A:$L,3,FALSE)*VLOOKUP(B26,Alimentos!$A:$L,7,FALSE) | I26: =C26/VLOOKUP(B26,Alimentos!$A:$L,3,FALSE)*VLOOKUP(B26,Alimentos!$A:$L,8,FALSE)
A27: Lanche | B27: Banana nanica | C27: 100 | D27: =VLOOKUP(B27,Alimentos!$A:$L,2,FALSE) | E27: =C27/VLOOKUP(B27,Alimentos!$A:$L,3,FALSE)*VLOOKUP(B27,Alimentos!$A:$L,4,FALSE) | F27: =C27/VLOOKUP(B27,Alimentos!$A:$L,3,FALSE)*VLOOKUP(B27,Alimentos!$A:$L,5,FALSE) | G27: =C27/VLOOKUP(B27,Alimentos!$A:$L,3,FALSE)*VLOOKUP(B27,Alimentos!$A:$L,6,FALSE) | H27: =C27/VLOOKUP(B27,Alimentos!$A:$L,3,FALSE)*VLOOKUP(B27,Alimentos!$A:$L,7,FALSE) | I27: =C27/VLOOKUP(B27,Alimentos!$A:$L,3,FALSE)*VLOOKUP(B27,Alimentos!$A:$L,8,FALSE)
A28: Lanche | B28: Aveia em flocos | C28: 40 | D28: =VLOOKUP(B28,Alimentos!$A:$L,2,FALSE) | E28: =C28/VLOOKUP(B28,Alimentos!$A:$L,3,FALSE)*VLOOKUP(B28,Alimentos!$A:$L,4,FALSE) | F28: =C28/VLOOKUP(B28,Alimentos!$A:$L,3,FALSE)*VLOOKUP(B28,Alimentos!$A:$L,5,FALSE) | G28: =C28/VLOOKUP(B28,Alimentos!$A:$L,3,FALSE)*VLOOKUP(B28,Alimentos!$A:$L,6,FALSE) | H28: =C28/VLOOKUP(B28,Alimentos!$A:$L,3,FALSE)*VLOOKUP(B28,Alimentos!$A:$L,7,FALSE) | I28: =C28/VLOOKUP(B28,Alimentos!$A:$L,3,FALSE)*VLOOKUP(B28,Alimentos!$A:$L,8,FALSE)
A29: Ceia | B29: Banana nanica | C29: 100 | D29: =VLOOKUP(B29,Alimentos!$A:$L,2,FALSE) | E29: =C29/VLOOKUP(B29,Alimentos!$A:$L,3,FALSE)*VLOOKUP(B29,Alimentos!$A:$L,4,FALSE) | F29: =C29/VLOOKUP(B29,Alimentos!$A:$L,3,FALSE)*VLOOKUP(B29,Alimentos!$A:$L,5,FALSE) | G29: =C29/VLOOKUP(B29,Alimentos!$A:$L,3,FALSE)*VLOOKUP(B29,Alimentos!$A:$L,6,FALSE) | H29: =C29/VLOOKUP(B29,Alimentos!$A:$L,3,FALSE)*VLOOKUP(B29,Alimentos!$A:$L,7,FALSE) | I29: =C29/VLOOKUP(B29,Alimentos!$A:$L,3,FALSE)*VLOOKUP(B29,Alimentos!$A:$L,8,FALSE) | J29: Pode deslocar para antes do Muay Thai
A31: Total da proposta | E31: =SUM(E6:E29) | F31: =SUM(F6:F29) | G31: =SUM(G6:G29) | H31: =SUM(H6:H29) | I31: =SUM(I6:I29)

Sheet Equivalências
A2: Trocas por nutriente principal
A3: Trocas igualam um nutriente, não todos os macros. Confira o total da dieta.
A5: Base | B5: Qtd. base | C5: Critério | D5: Alternativa | E5: Qtd. equivalente | F5: Unidade | G5: kcal base | H5: kcal alternativa | I5: Diferença kcal | J5: Proteína alt. | K5: Carboidrato alt. | L5: Gordura alt. | M5: Observação
A6: Peito de frango cozido | B6: 100 | C6: Proteína | D6: Ovo inteiro cozido | E6: =B6/VLOOKUP(A6,Alimentos!$A:$L,3,FALSE)*VLOOKUP(A6,Alimentos!$A:$L,IF(C6="Proteína",5,IF(C6="Carboidrato",6,7)),FALSE)/VLOOKUP(D6,Alimentos!$A:$L,IF(C6="Proteína",5,IF(C6="Carboidrato",6,7)),FALSE)*VLOOKUP(D6,Alimentos!$A:$L,3,FALSE) | F6: =VLOOKUP(D6,Alimentos!$A:$L,2,FALSE) | G6: =B6/VLOOKUP(A6,Alimentos!$A:$L,3,FALSE)*VLOOKUP(A6,Alimentos!$A:$L,4,FALSE) | H6: =E6/VLOOKUP(D6,Alimentos!$A:$L,3,FALSE)*VLOOKUP(D6,Alimentos!$A:$L,4,FALSE) | I6: =H6-G6 | J6: =E6/VLOOKUP(D6,Alimentos!$A:$L,3,FALSE)*VLOOKUP(D6,Alimentos!$A:$L,5,FALSE) | K6: =E6/VLOOKUP(D6,Alimentos!$A:$L,3,FALSE)*VLOOKUP(D6,Alimentos!$A:$L,6,FALSE) | L6: =E6/VLOOKUP(D6,Alimentos!$A:$L,3,FALSE)*VLOOKUP(D6,Alimentos!$A:$L,7,FALSE) | M6: Ovos: dividir gramas por 50 para estimar unidades. A gordura e as calorias aumentam nesta troca.
A7: Ovo inteiro cozido | B7: 150 | C7: Proteína | D7: Peito de frango cozido | E7: =B7/VLOOKUP(A7,Alimentos!$A:$L,3,FALSE)*VLOOKUP(A7,Alimentos!$A:$L,IF(C7="Proteína",5,IF(C7="Carboidrato",6,7)),FALSE)/VLOOKUP(D7,Alimentos!$A:$L,IF(C7="Proteína",5,IF(C7="Carboidrato",6,7)),FALSE)*VLOOKUP(D7,Alimentos!$A:$L,3,FALSE) | F7: =VLOOKUP(D7,Alimentos!$A:$L,2,FALSE) | G7: =B7/VLOOKUP(A7,Alimentos!$A:$L,3,FALSE)*VLOOKUP(A7,Alimentos!$A:$L,4,FALSE) | H7: =E7/VLOOKUP(D7,Alimentos!$A:$L,3,FALSE)*VLOOKUP(D7,Alimentos!$A:$L,4,FALSE) | I7: =H7-G7 | J7: =E7/VLOOKUP(D7,Alimentos!$A:$L,3,FALSE)*VLOOKUP(D7,Alimentos!$A:$L,5,FALSE) | K7: =E7/VLOOKUP(D7,Alimentos!$A:$L,3,FALSE)*VLOOKUP(D7,Alimentos!$A:$L,6,FALSE) | L7: =E7/VLOOKUP(D7,Alimentos!$A:$L,3,FALSE)*VLOOKUP(D7,Alimentos!$A:$L,7,FALSE)
A8: Whey (rótulo a conferir) | B8: 30 | C8: Proteína | D8: Peito de frango cozido | E8: =B8/VLOOKUP(A8,Alimentos!$A:$L,3,FALSE)*VLOOKUP(A8,Alimentos!$A:$L,IF(C8="Proteína",5,IF(C8="Carboidrato",6,7)),FALSE)/VLOOKUP(D8,Alimentos!$A:$L,IF(C8="Proteína",5,IF(C8="Carboidrato",6,7)),FALSE)*VLOOKUP(D8,Alimentos!$A:$L,3,FALSE) | F8: =VLOOKUP(D8,Alimentos!$A:$L,2,FALSE) | G8: =B8/VLOOKUP(A8,Alimentos!$A:$L,3,FALSE)*VLOOKUP(A8,Alimentos!$A:$L,4,FALSE) | H8: =E8/VLOOKUP(D8,Alimentos!$A:$L,3,FALSE)*VLOOKUP(D8,Alimentos!$A:$L,4,FALSE) | I8: =H8-G8 | J8: =E8/VLOOKUP(D8,Alimentos!$A:$L,3,FALSE)*VLOOKUP(D8,Alimentos!$A:$L,5,FALSE) | K8: =E8/VLOOKUP(D8,Alimentos!$A:$L,3,FALSE)*VLOOKUP(D8,Alimentos!$A:$L,6,FALSE) | L8: =E8/VLOOKUP(D8,Alimentos!$A:$L,3,FALSE)*VLOOKUP(D8,Alimentos!$A:$L,7,FALSE)
A9: Whey (rótulo a conferir) | B9: 30 | C9: Proteína | D9: Ovo inteiro cozido | E9: =B9/VLOOKUP(A9,Alimentos!$A:$L,3,FALSE)*VLOOKUP(A9,Alimentos!$A:$L,IF(C9="Proteína",5,IF(C9="Carboidrato",6,7)),FALSE)/VLOOKUP(D9,Alimentos!$A:$L,IF(C9="Proteína",5,IF(C9="Carboidrato",6,7)),FALSE)*VLOOKUP(D9,Alimentos!$A:$L,3,FALSE) | F9: =VLOOKUP(D9,Alimentos!$A:$L,2,FALSE) | G9: =B9/VLOOKUP(A9,Alimentos!$A:$L,3,FALSE)*VLOOKUP(A9,Alimentos!$A:$L,4,FALSE) | H9: =E9/VLOOKUP(D9,Alimentos!$A:$L,3,FALSE)*VLOOKUP(D9,Alimentos!$A:$L,4,FALSE) | I9: =H9-G9 | J9: =E9/VLOOKUP(D9,Alimentos!$A:$L,3,FALSE)*VLOOKUP(D9,Alimentos!$A:$L,5,FALSE) | K9: =E9/VLOOKUP(D9,Alimentos!$A:$L,3,FALSE)*VLOOKUP(D9,Alimentos!$A:$L,6,FALSE) | L9: =E9/VLOOKUP(D9,Alimentos!$A:$L,3,FALSE)*VLOOKUP(D9,Alimentos!$A:$L,7,FALSE)
A10: Peito de frango cozido | B10: 100 | C10: Proteína | D10: Merluza assada | E10: =B10/VLOOKUP(A10,Alimentos!$A:$L,3,FALSE)*VLOOKUP(A10,Alimentos!$A:$L,IF(C10="Proteína",5,IF(C10="Carboidrato",6,7)),FALSE)/VLOOKUP(D10,Alimentos!$A:$L,IF(C10="Proteína",5,IF(C10="Carboidrato",6,7)),FALSE)*VLOOKUP(D10,Alimentos!$A:$L,3,FALSE) | F10: =VLOOKUP(D10,Alimentos!$A:$L,2,FALSE) | G10: =B10/VLOOKUP(A10,Alimentos!$A:$L,3,FALSE)*VLOOKUP(A10,Alimentos!$A:$L,4,FALSE) | H10: =E10/VLOOKUP(D10,Alimentos!$A:$L,3,FALSE)*VLOOKUP(D10,Alimentos!$A:$L,4,FALSE) | I10: =H10-G10 | J10: =E10/VLOOKUP(D10,Alimentos!$A:$L,3,FALSE)*VLOOKUP(D10,Alimentos!$A:$L,5,FALSE) | K10: =E10/VLOOKUP(D10,Alimentos!$A:$L,3,FALSE)*VLOOKUP(D10,Alimentos!$A:$L,6,FALSE) | L10: =E10/VLOOKUP(D10,Alimentos!$A:$L,3,FALSE)*VLOOKUP(D10,Alimentos!$A:$L,7,FALSE)
A11: Ovo inteiro cozido | B11: 150 | C11: Proteína | D11: Clara de ovo cozida | E11: =B11/VLOOKUP(A11,Alimentos!$A:$L,3,FALSE)*VLOOKUP(A11,Alimentos!$A:$L,IF(C11="Proteína",5,IF(C11="Carboidrato",6,7)),FALSE)/VLOOKUP(D11,Alimentos!$A:$L,IF(C11="Proteína",5,IF(C11="Carboidrato",6,7)),FALSE)*VLOOKUP(D11,Alimentos!$A:$L,3,FALSE) | F11: =VLOOKUP(D11,Alimentos!$A:$L,2,FALSE) | G11: =B11/VLOOKUP(A11,Alimentos!$A:$L,3,FALSE)*VLOOKUP(A11,Alimentos!$A:$L,4,FALSE) | H11: =E11/VLOOKUP(D11,Alimentos!$A:$L,3,FALSE)*VLOOKUP(D11,Alimentos!$A:$L,4,FALSE) | I11: =H11-G11 | J11: =E11/VLOOKUP(D11,Alimentos!$A:$L,3,FALSE)*VLOOKUP(D11,Alimentos!$A:$L,5,FALSE) | K11: =E11/VLOOKUP(D11,Alimentos!$A:$L,3,FALSE)*VLOOKUP(D11,Alimentos!$A:$L,6,FALSE) | L11: =E11/VLOOKUP(D11,Alimentos!$A:$L,3,FALSE)*VLOOKUP(D11,Alimentos!$A:$L,7,FALSE)
A12: Arroz branco cozido | B12: 150 | C12: Carboidrato | D12: Batata inglesa cozida | E12: =B12/VLOOKUP(A12,Alimentos!$A:$L,3,FALSE)*VLOOKUP(A12,Alimentos!$A:$L,IF(C12="Proteína",5,IF(C12="Carboidrato",6,7)),FALSE)/VLOOKUP(D12,Alimentos!$A:$L,IF(C12="Proteína",5,IF(C12="Carboidrato",6,7)),FALSE)*VLOOKUP(D12,Alimentos!$A:$L,3,FALSE) | F12: =VLOOKUP(D12,Alimentos!$A:$L,2,FALSE) | G12: =B12/VLOOKUP(A12,Alimentos!$A:$L,3,FALSE)*VLOOKUP(A12,Alimentos!$A:$L,4,FALSE) | H12: =E12/VLOOKUP(D12,Alimentos!$A:$L,3,FALSE)*VLOOKUP(D12,Alimentos!$A:$L,4,FALSE) | I12: =H12-G12 | J12: =E12/VLOOKUP(D12,Alimentos!$A:$L,3,FALSE)*VLOOKUP(D12,Alimentos!$A:$L,5,FALSE) | K12: =E12/VLOOKUP(D12,Alimentos!$A:$L,3,FALSE)*VLOOKUP(D12,Alimentos!$A:$L,6,FALSE) | L12: =E12/VLOOKUP(D12,Alimentos!$A:$L,3,FALSE)*VLOOKUP(D12,Alimentos!$A:$L,7,FALSE)
A13: Arroz branco cozido | B13: 150 | C13: Carboidrato | D13: Batata doce cozida | E13: =B13/VLOOKUP(A13,Alimentos!$A:$L,3,FALSE)*VLOOKUP(A13,Alimentos!$A:$L,IF(C13="Proteína",5,IF(C13="Carboidrato",6,7)),FALSE)/VLOOKUP(D13,Alimentos!$A:$L,IF(C13="Proteína",5,IF(C13="Carboidrato",6,7)),FALSE)*VLOOKUP(D13,Alimentos!$A:$L,3,FALSE) | F13: =VLOOKUP(D13,Alimentos!$A:$L,2,FALSE) | G13: =B13/VLOOKUP(A13,Alimentos!$A:$L,3,FALSE)*VLOOKUP(A13,Alimentos!$A:$L,4,FALSE) | H13: =E13/VLOOKUP(D13,Alimentos!$A:$L,3,FALSE)*VLOOKUP(D13,Alimentos!$A:$L,4,FALSE) | I13: =H13-G13 | J13: =E13/VLOOKUP(D13,Alimentos!$A:$L,3,FALSE)*VLOOKUP(D13,Alimentos!$A:$L,5,FALSE) | K13: =E13/VLOOKUP(D13,Alimentos!$A:$L,3,FALSE)*VLOOKUP(D13,Alimentos!$A:$L,6,FALSE) | L13: =E13/VLOOKUP(D13,Alimentos!$A:$L,3,FALSE)*VLOOKUP(D13,Alimentos!$A:$L,7,FALSE)
A14: Pão integral | B14: 50 | C14: Carboidrato | D14: Aveia em flocos | E14: =B14/VLOOKUP(A14,Alimentos!$A:$L,3,FALSE)*VLOOKUP(A14,Alimentos!$A:$L,IF(C14="Proteína",5,IF(C14="Carboidrato",6,7)),FALSE)/VLOOKUP(D14,Alimentos!$A:$L,IF(C14="Proteína",5,IF(C14="Carboidrato",6,7)),FALSE)*VLOOKUP(D14,Alimentos!$A:$L,3,FALSE) | F14: =VLOOKUP(D14,Alimentos!$A:$L,2,FALSE) | G14: =B14/VLOOKUP(A14,Alimentos!$A:$L,3,FALSE)*VLOOKUP(A14,Alimentos!$A:$L,4,FALSE) | H14: =E14/VLOOKUP(D14,Alimentos!$A:$L,3,FALSE)*VLOOKUP(D14,Alimentos!$A:$L,4,FALSE) | I14: =H14-G14 | J14: =E14/VLOOKUP(D14,Alimentos!$A:$L,3,FALSE)*VLOOKUP(D14,Alimentos!$A:$L,5,FALSE) | K14: =E14/VLOOKUP(D14,Alimentos!$A:$L,3,FALSE)*VLOOKUP(D14,Alimentos!$A:$L,6,FALSE) | L14: =E14/VLOOKUP(D14,Alimentos!$A:$L,3,FALSE)*VLOOKUP(D14,Alimentos!$A:$L,7,FALSE)
A15: Banana nanica | B15: 100 | C15: Carboidrato | D15: Laranja pera | E15: =B15/VLOOKUP(A15,Alimentos!$A:$L,3,FALSE)*VLOOKUP(A15,Alimentos!$A:$L,IF(C15="Proteína",5,IF(C15="Carboidrato",6,7)),FALSE)/VLOOKUP(D15,Alimentos!$A:$L,IF(C15="Proteína",5,IF(C15="Carboidrato",6,7)),FALSE)*VLOOKUP(D15,Alimentos!$A:$L,3,FALSE) | F15: =VLOOKUP(D15,Alimentos!$A:$L,2,FALSE) | G15: =B15/VLOOKUP(A15,Alimentos!$A:$L,3,FALSE)*VLOOKUP(A15,Alimentos!$A:$L,4,FALSE) | H15: =E15/VLOOKUP(D15,Alimentos!$A:$L,3,FALSE)*VLOOKUP(D15,Alimentos!$A:$L,4,FALSE) | I15: =H15-G15 | J15: =E15/VLOOKUP(D15,Alimentos!$A:$L,3,FALSE)*VLOOKUP(D15,Alimentos!$A:$L,5,FALSE) | K15: =E15/VLOOKUP(D15,Alimentos!$A:$L,3,FALSE)*VLOOKUP(D15,Alimentos!$A:$L,6,FALSE) | L15: =E15/VLOOKUP(D15,Alimentos!$A:$L,3,FALSE)*VLOOKUP(D15,Alimentos!$A:$L,7,FALSE)
A16: Feijão carioca cozido | B16: 100 | C16: Carboidrato | D16: Feijão preto cozido | E16: =B16/VLOOKUP(A16,Alimentos!$A:$L,3,FALSE)*VLOOKUP(A16,Alimentos!$A:$L,IF(C16="Proteína",5,IF(C16="Carboidrato",6,7)),FALSE)/VLOOKUP(D16,Alimentos!$A:$L,IF(C16="Proteína",5,IF(C16="Carboidrato",6,7)),FALSE)*VLOOKUP(D16,Alimentos!$A:$L,3,FALSE) | F16: =VLOOKUP(D16,Alimentos!$A:$L,2,FALSE) | G16: =B16/VLOOKUP(A16,Alimentos!$A:$L,3,FALSE)*VLOOKUP(A16,Alimentos!$A:$L,4,FALSE) | H16: =E16/VLOOKUP(D16,Alimentos!$A:$L,3,FALSE)*VLOOKUP(D16,Alimentos!$A:$L,4,FALSE) | I16: =H16-G16 | J16: =E16/VLOOKUP(D16,Alimentos!$A:$L,3,FALSE)*VLOOKUP(D16,Alimentos!$A:$L,5,FALSE) | K16: =E16/VLOOKUP(D16,Alimentos!$A:$L,3,FALSE)*VLOOKUP(D16,Alimentos!$A:$L,6,FALSE) | L16: =E16/VLOOKUP(D16,Alimentos!$A:$L,3,FALSE)*VLOOKUP(D16,Alimentos!$A:$L,7,FALSE)
A17: Feijão carioca cozido | B17: 100 | C17: Carboidrato | D17: Lentilha cozida | E17: =B17/VLOOKUP(A17,Alimentos!$A:$L,3,FALSE)*VLOOKUP(A17,Alimentos!$A:$L,IF(C17="Proteína",5,IF(C17="Carboidrato",6,7)),FALSE)/VLOOKUP(D17,Alimentos!$A:$L,IF(C17="Proteína",5,IF(C17="Carboidrato",6,7)),FALSE)*VLOOKUP(D17,Alimentos!$A:$L,3,FALSE) | F17: =VLOOKUP(D17,Alimentos!$A:$L,2,FALSE) | G17: =B17/VLOOKUP(A17,Alimentos!$A:$L,3,FALSE)*VLOOKUP(A17,Alimentos!$A:$L,4,FALSE) | H17: =E17/VLOOKUP(D17,Alimentos!$A:$L,3,FALSE)*VLOOKUP(D17,Alimentos!$A:$L,4,FALSE) | I17: =H17-G17 | J17: =E17/VLOOKUP(D17,Alimentos!$A:$L,3,FALSE)*VLOOKUP(D17,Alimentos!$A:$L,5,FALSE) | K17: =E17/VLOOKUP(D17,Alimentos!$A:$L,3,FALSE)*VLOOKUP(D17,Alimentos!$A:$L,6,FALSE) | L17: =E17/VLOOKUP(D17,Alimentos!$A:$L,3,FALSE)*VLOOKUP(D17,Alimentos!$A:$L,7,FALSE)
A18: Peito de frango cozido | B18: 100 | C18: Proteína | D18: Carne bovina patinho grelhado | E18: =B18/VLOOKUP(A18,Alimentos!$A:$L,3,FALSE)*VLOOKUP(A18,Alimentos!$A:$L,IF(C18="Proteína",5,IF(C18="Carboidrato",6,7)),FALSE)/VLOOKUP(D18,Alimentos!$A:$L,IF(C18="Proteína",5,IF(C18="Carboidrato",6,7)),FALSE)*VLOOKUP(D18,Alimentos!$A:$L,3,FALSE) | F18: =VLOOKUP(D18,Alimentos!$A:$L,2,FALSE) | G18: =B18/VLOOKUP(A18,Alimentos!$A:$L,3,FALSE)*VLOOKUP(A18,Alimentos!$A:$L,4,FALSE) | H18: =E18/VLOOKUP(D18,Alimentos!$A:$L,3,FALSE)*VLOOKUP(D18,Alimentos!$A:$L,4,FALSE) | I18: =H18-G18 | J18: =E18/VLOOKUP(D18,Alimentos!$A:$L,3,FALSE)*VLOOKUP(D18,Alimentos!$A:$L,5,FALSE) | K18: =E18/VLOOKUP(D18,Alimentos!$A:$L,3,FALSE)*VLOOKUP(D18,Alimentos!$A:$L,6,FALSE) | L18: =E18/VLOOKUP(D18,Alimentos!$A:$L,3,FALSE)*VLOOKUP(D18,Alimentos!$A:$L,7,FALSE) | M18: Patinho moído ou bife magro; pesar pronto sem óleo.
A19: Peito de frango cozido | B19: 100 | C19: Proteína | D19: Filé de tilápia grelhado | E19: =B19/VLOOKUP(A19,Alimentos!$A:$L,3,FALSE)*VLOOKUP(A19,Alimentos!$A:$L,IF(C19="Proteína",5,IF(C19="Carboidrato",6,7)),FALSE)/VLOOKUP(D19,Alimentos!$A:$L,IF(C19="Proteína",5,IF(C19="Carboidrato",6,7)),FALSE)*VLOOKUP(D19,Alimentos!$A:$L,3,FALSE) | F19: =VLOOKUP(D19,Alimentos!$A:$L,2,FALSE) | G19: =B19/VLOOKUP(A19,Alimentos!$A:$L,3,FALSE)*VLOOKUP(A19,Alimentos!$A:$L,4,FALSE) | H19: =E19/VLOOKUP(D19,Alimentos!$A:$L,3,FALSE)*VLOOKUP(D19,Alimentos!$A:$L,4,FALSE) | I19: =H19-G19 | J19: =E19/VLOOKUP(D19,Alimentos!$A:$L,3,FALSE)*VLOOKUP(D19,Alimentos!$A:$L,5,FALSE) | K19: =E19/VLOOKUP(D19,Alimentos!$A:$L,3,FALSE)*VLOOKUP(D19,Alimentos!$A:$L,6,FALSE) | L19: =E19/VLOOKUP(D19,Alimentos!$A:$L,3,FALSE)*VLOOKUP(D19,Alimentos!$A:$L,7,FALSE) | M19: Pesar pronto sem óleo.
A20: Peito de frango cozido | B20: 100 | C20: Proteína | D20: Atum ralado em conserva em água | E20: =B20/VLOOKUP(A20,Alimentos!$A:$L,3,FALSE)*VLOOKUP(A20,Alimentos!$A:$L,IF(C20="Proteína",5,IF(C20="Carboidrato",6,7)),FALSE)/VLOOKUP(D20,Alimentos!$A:$L,IF(C20="Proteína",5,IF(C20="Carboidrato",6,7)),FALSE)*VLOOKUP(D20,Alimentos!$A:$L,3,FALSE) | F20: =VLOOKUP(D20,Alimentos!$A:$L,2,FALSE) | G20: =B20/VLOOKUP(A20,Alimentos!$A:$L,3,FALSE)*VLOOKUP(A20,Alimentos!$A:$L,4,FALSE) | H20: =E20/VLOOKUP(D20,Alimentos!$A:$L,3,FALSE)*VLOOKUP(D20,Alimentos!$A:$L,4,FALSE) | I20: =H20-G20 | J20: =E20/VLOOKUP(D20,Alimentos!$A:$L,3,FALSE)*VLOOKUP(D20,Alimentos!$A:$L,5,FALSE) | K20: =E20/VLOOKUP(D20,Alimentos!$A:$L,3,FALSE)*VLOOKUP(D20,Alimentos!$A:$L,6,FALSE) | L20: =E20/VLOOKUP(D20,Alimentos!$A:$L,3,FALSE)*VLOOKUP(D20,Alimentos!$A:$L,7,FALSE) | M20: Pesar bem escorrido.
A21: Arroz branco cozido | B21: 150 | C21: Carboidrato | D21: Mandioca cozida | E21: =B21/VLOOKUP(A21,Alimentos!$A:$L,3,FALSE)*VLOOKUP(A21,Alimentos!$A:$L,IF(C21="Proteína",5,IF(C21="Carboidrato",6,7)),FALSE)/VLOOKUP(D21,Alimentos!$A:$L,IF(C21="Proteína",5,IF(C21="Carboidrato",6,7)),FALSE)*VLOOKUP(D21,Alimentos!$A:$L,3,FALSE) | F21: =VLOOKUP(D21,Alimentos!$A:$L,2,FALSE) | G21: =B21/VLOOKUP(A21,Alimentos!$A:$L,3,FALSE)*VLOOKUP(A21,Alimentos!$A:$L,4,FALSE) | H21: =E21/VLOOKUP(D21,Alimentos!$A:$L,3,FALSE)*VLOOKUP(D21,Alimentos!$A:$L,4,FALSE) | I21: =H21-G21 | J21: =E21/VLOOKUP(D21,Alimentos!$A:$L,3,FALSE)*VLOOKUP(D21,Alimentos!$A:$L,5,FALSE) | K21: =E21/VLOOKUP(D21,Alimentos!$A:$L,3,FALSE)*VLOOKUP(D21,Alimentos!$A:$L,6,FALSE) | L21: =E21/VLOOKUP(D21,Alimentos!$A:$L,3,FALSE)*VLOOKUP(D21,Alimentos!$A:$L,7,FALSE) | M21: Aipim/macaxeira cozida sem óleo.
A22: Arroz branco cozido | B22: 150 | C22: Carboidrato | D22: Macarrão de sêmola cozido | E22: =B22/VLOOKUP(A22,Alimentos!$A:$L,3,FALSE)*VLOOKUP(A22,Alimentos!$A:$L,IF(C22="Proteína",5,IF(C22="Carboidrato",6,7)),FALSE)/VLOOKUP(D22,Alimentos!$A:$L,IF(C22="Proteína",5,IF(C22="Carboidrato",6,7)),FALSE)*VLOOKUP(D22,Alimentos!$A:$L,3,FALSE) | F22: =VLOOKUP(D22,Alimentos!$A:$L,2,FALSE) | G22: =B22/VLOOKUP(A22,Alimentos!$A:$L,3,FALSE)*VLOOKUP(A22,Alimentos!$A:$L,4,FALSE) | H22: =E22/VLOOKUP(D22,Alimentos!$A:$L,3,FALSE)*VLOOKUP(D22,Alimentos!$A:$L,4,FALSE) | I22: =H22-G22 | J22: =E22/VLOOKUP(D22,Alimentos!$A:$L,3,FALSE)*VLOOKUP(D22,Alimentos!$A:$L,5,FALSE) | K22: =E22/VLOOKUP(D22,Alimentos!$A:$L,3,FALSE)*VLOOKUP(D22,Alimentos!$A:$L,6,FALSE) | L22: =E22/VLOOKUP(D22,Alimentos!$A:$L,3,FALSE)*VLOOKUP(D22,Alimentos!$A:$L,7,FALSE) | M22: Pesar cozido; molho contabilizado à parte.
A23: Arroz branco cozido | B23: 150 | C23: Carboidrato | D23: Cuscuz de milho cozido | E23: =B23/VLOOKUP(A23,Alimentos!$A:$L,3,FALSE)*VLOOKUP(A23,Alimentos!$A:$L,IF(C23="Proteína",5,IF(C23="Carboidrato",6,7)),FALSE)/VLOOKUP(D23,Alimentos!$A:$L,IF(C23="Proteína",5,IF(C23="Carboidrato",6,7)),FALSE)*VLOOKUP(D23,Alimentos!$A:$L,3,FALSE) | F23: =VLOOKUP(D23,Alimentos!$A:$L,2,FALSE) | G23: =B23/VLOOKUP(A23,Alimentos!$A:$L,3,FALSE)*VLOOKUP(A23,Alimentos!$A:$L,4,FALSE) | H23: =E23/VLOOKUP(D23,Alimentos!$A:$L,3,FALSE)*VLOOKUP(D23,Alimentos!$A:$L,4,FALSE) | I23: =H23-G23 | J23: =E23/VLOOKUP(D23,Alimentos!$A:$L,3,FALSE)*VLOOKUP(D23,Alimentos!$A:$L,5,FALSE) | K23: =E23/VLOOKUP(D23,Alimentos!$A:$L,3,FALSE)*VLOOKUP(D23,Alimentos!$A:$L,6,FALSE) | L23: =E23/VLOOKUP(D23,Alimentos!$A:$L,3,FALSE)*VLOOKUP(D23,Alimentos!$A:$L,7,FALSE) | M23: Pesar cozido; manteiga contabilizada à parte.
A24: Azeite | B24: 10 | C24: Gordura | D24: Pasta de amendoim integral | E24: =B24/VLOOKUP(A24,Alimentos!$A:$L,3,FALSE)*VLOOKUP(A24,Alimentos!$A:$L,IF(C24="Proteína",5,IF(C24="Carboidrato",6,7)),FALSE)/VLOOKUP(D24,Alimentos!$A:$L,IF(C24="Proteína",5,IF(C24="Carboidrato",6,7)),FALSE)*VLOOKUP(D24,Alimentos!$A:$L,3,FALSE) | F24: =VLOOKUP(D24,Alimentos!$A:$L,2,FALSE) | G24: =B24/VLOOKUP(A24,Alimentos!$A:$L,3,FALSE)*VLOOKUP(A24,Alimentos!$A:$L,4,FALSE) | H24: =E24/VLOOKUP(D24,Alimentos!$A:$L,3,FALSE)*VLOOKUP(D24,Alimentos!$A:$L,4,FALSE) | I24: =H24-G24 | J24: =E24/VLOOKUP(D24,Alimentos!$A:$L,3,FALSE)*VLOOKUP(D24,Alimentos!$A:$L,5,FALSE) | K24: =E24/VLOOKUP(D24,Alimentos!$A:$L,3,FALSE)*VLOOKUP(D24,Alimentos!$A:$L,6,FALSE) | L24: =E24/VLOOKUP(D24,Alimentos!$A:$L,3,FALSE)*VLOOKUP(D24,Alimentos!$A:$L,7,FALSE) | M24: Atenção: adiciona 5 g de proteína e 4 g de carbo.
A25: Azeite | B25: 10 | C25: Gordura | D25: Castanha-do-pará | E25: =B25/VLOOKUP(A25,Alimentos!$A:$L,3,FALSE)*VLOOKUP(A25,Alimentos!$A:$L,IF(C25="Proteína",5,IF(C25="Carboidrato",6,7)),FALSE)/VLOOKUP(D25,Alimentos!$A:$L,IF(C25="Proteína",5,IF(C25="Carboidrato",6,7)),FALSE)*VLOOKUP(D25,Alimentos!$A:$L,3,FALSE) | F25: =VLOOKUP(D25,Alimentos!$A:$L,2,FALSE) | G25: =B25/VLOOKUP(A25,Alimentos!$A:$L,3,FALSE)*VLOOKUP(A25,Alimentos!$A:$L,4,FALSE) | H25: =E25/VLOOKUP(D25,Alimentos!$A:$L,3,FALSE)*VLOOKUP(D25,Alimentos!$A:$L,4,FALSE) | I25: =H25-G25 | J25: =E25/VLOOKUP(D25,Alimentos!$A:$L,3,FALSE)*VLOOKUP(D25,Alimentos!$A:$L,5,FALSE) | K25: =E25/VLOOKUP(D25,Alimentos!$A:$L,3,FALSE)*VLOOKUP(D25,Alimentos!$A:$L,6,FALSE) | L25: =E25/VLOOKUP(D25,Alimentos!$A:$L,3,FALSE)*VLOOKUP(D25,Alimentos!$A:$L,7,FALSE) | M25: Aproximadamente 3 unidades médias.

Sheet Alimentação
A2: Registro diário de alimentação
A3: Consumo confirmado. Quantidades na unidade-base. Sem cálculo = macros desconhecidos, nunca zero.
A5: Data | B5: Refeição | C5: Alimento | D5: Quantidade | E5: Unidade | F5: kcal | G5: Proteína g | H5: Carboidrato g | I5: Gordura g | J5: Fibra g | K5: Medição | L5: Observação | M5: Conferência | N5: ID lançamento | O5: Favorita / versão | P5: Fonte | Q5: Cálculo

Sheet Diário
A2: Resumo diário
A3: Uma linha por dia. Vazio = não informado; zero só quando digitado. Totais escritos pelo script.
A5: Data | B5: Peso kg | C5: Cintura cm | D5: Sono h | E5: Passos | F5: Cardio min | G5: Atividade min | H5: Atividade | I5: Fome 1–5 | J5: Cansaço 1–5 | K5: Dor 0–10 | L5: Registro alimentar | M5: Observações | N5: Objetivo | O5: Meta | P5: Ficha | Q5: kcal | R5: Proteína g | S5: Carboidrato g | T5: Gordura g | U5: Fibra g | V5: Itens sem cálculo | W5: Itens estimados | X5: Treinos | Y5: Estado do dia

Sheet Semanas
A2: Evolução semanal
A3: Uma linha por semana (segunda a domingo), gravada como valores com o objetivo, a meta e a ficha daquela semana.
A5: Início | B5: Fim | C5: Objetivo | D5: Meta | E5: Ficha | F5: Transição na semana | G5: Pesagens | H5: Peso médio 7d | I5: Variação kg | J5: Variação %/sem | K5: Cintura | L5: Variação cintura | M5: Dias com registro | N5: Dias completos | O5: kcal média | P5: Proteína média | Q5: Carboidrato médio | R5: Gordura média | S5: Fibra média | T5: Aderência kcal | U5: Aderência proteína | V5: Aderência gordura | W5: Cobertura alimentar | X5: Itens sem cálculo | Y5: Treinos | Z5: Meta treinos | AA5: Volume work | AB5: Exercícios com progressão | AC5: Sono médio | AD5: Fome média | AE5: Cansaço médio | AF5: Dor máx | AG5: Passos médios | AH5: Cardio min | AI5: Atividades | AJ5: Suficiência de dados | AK5: Situação | AL5: Sinais | AM5: Motivos | AN5: Recomendação | AO5: Motivo da recomendação | AP5: Próxima revisão | AQ5: Calculado em

Sheet Medidas e fotos
A2: Medidas e fotos padronizadas
A3: Cintura semanal; outras medidas e fotos a cada 4 semanas, mesma luz, distância e postura.
A5: Data | B5: Cintura umbigo cm | C5: Quadril cm | D5: Peito cm | E5: Braço direito cm | F5: Coxa direita cm | G5: Frente: link | H5: Lado: link | I5: Costas: link | J5: Condições / observações | K5: Objetivo

Sheet Revisões
A2: Decisões e adaptação
A3: Toda mudança de objetivo, meta ou ficha fica registrada aqui. A planilha não muda metas sozinha.
A5: Data | B5: Área | C5: Observação / motivo | D5: Alteração | E5: Revisor | F5: Status | G5: Próxima revisão | H5: Resultado | I5: Objetivo | J5: Meta | K5: Ficha | L5: Recomendação
A6: 46280 | B6: Ficha inicial | C6: Ficha do chat: Upper 20, Lower 16 e Full Body 19 séries após adaptação. Revisar tolerância junto ao Muay Thai. | D6: Adaptação separada em coluna própria. Não avançar automaticamente para o volume posterior. | E6: Luan | F6: A revisar | K6: F001
A7: 46280 | B7: Dieta inicial | C7: Soma das porções originais com whey e leite podia exceder a faixa proteica. | D7: Proposta atual: frango 100 g nas refeições, whey 10 g no lanche e arroz 200 g; conferir consumo real. | E7: Luan | F7: A revisar | K7: F001
A8: 46293 | B8: Sistema 3.0 | C8: Ambiguidade de séries, unidades e completude | D8: Work sets separadas; ficha F002; unidade explícita; correção/desfazer; favoritas pessoais | E8: Luan / atualização autorizada | F8: Aplicado | I8: O001 | J8: M001 | K8: F002
A9: 46293 | B9: Alimentação | C9: Favoritas pré-configuradas não eram individuais | D9: Favoritas e ingredientes iniciam vazios; históricos alimentares preservados vazios | E9: Luan | F9: Aplicado | I9: O001 | J9: M001 | K9: F002
A10: 46293 | B10: Automação 3.0 | C10: Parcial e retomada; conclusão explícita; sequência contínua; unidades obrigatórias; correção e desfazer; alimentos sem cálculo; Ação rápida no celular. | D10: Testes de fluxo aprovados nos dois projetos; registros temporários removidos. | I10: O001 | J10: M001 | K10: F002

Sheet Alimentos
A2: Base de alimentos e macros
A3: Unidade-base e porção-base definem os nutrientes. Medida caseira é opcional. Não converter ml em g sem densidade.
A5: Alimento único | B5: Unidade-base | C5: Base | D5: kcal | E5: Proteína g | F5: Carboidrato g | G5: Gordura g | H5: Fibra g | I5: Referência | J5: Como medir | K5: Link da fonte | L5: Cadastro válido | M5: Medida caseira | N5: Base por medida | O5: Qualidade da referência
A6: Ovo inteiro cozido | B6: g | C6: 100 | D6: 146 | E6: 13.3 | F6: 0.6 | G6: 9.5 | H6: 0 | I6: TACO 4ª ed.; pelo nome | J6: 50 g sem casca por ovo, estimativa | K6: https://nepa.unicamp.br/wp-content/uploads/sites/27/2023/10/taco_4_edicao_ampliada_e_revisada.pdf | L6: =IF(A6="","",IF(AND(ISNUMBER(C6),C6>0,COUNT(D6:H6)=5),"OK","Rever macros")) | M6: un | N6: 50 | O6: Referência cadastrada — não auditada nesta revisão
A7: Peito de frango cozido | B7: g | C7: 100 | D7: 163 | E7: 31.5 | F7: 0 | G7: 3.2 | H7: 0 | I7: TACO 4ª ed.; pelo nome | J7: Pesar pronto; óleo separado | K7: https://nepa.unicamp.br/wp-content/uploads/sites/27/2023/10/taco_4_edicao_ampliada_e_revisada.pdf | L7: =IF(A7="","",IF(AND(ISNUMBER(C7),C7>0,COUNT(D7:H7)=5),"OK","Rever macros")) | O7: Referência cadastrada — não auditada nesta revisão
A8: Arroz branco cozido | B8: g | C8: 100 | D8: 128 | E8: 2.5 | F8: 28.1 | G8: 0.2 | H8: 1.6 | I8: TACO 4ª ed.; pelo nome | J8: Pesar pronto; óleo separado | K8: https://nepa.unicamp.br/wp-content/uploads/sites/27/2023/10/taco_4_edicao_ampliada_e_revisada.pdf | L8: =IF(A8="","",IF(AND(ISNUMBER(C8),C8>0,COUNT(D8:H8)=5),"OK","Rever macros")) | O8: Referência cadastrada — não auditada nesta revisão
A9: Feijão carioca cozido | B9: g | C9: 100 | D9: 76 | E9: 4.8 | F9: 13.6 | G9: 0.5 | H9: 8.5 | I9: TACO 4ª ed.; pelo nome | J9: Caldo e grãos conforme preparo | K9: https://nepa.unicamp.br/wp-content/uploads/sites/27/2023/10/taco_4_edicao_ampliada_e_revisada.pdf | L9: =IF(A9="","",IF(AND(ISNUMBER(C9),C9>0,COUNT(D9:H9)=5),"OK","Rever macros")) | O9: Referência cadastrada — não auditada nesta revisão
A10: Pão integral | B10: g | C10: 100 | D10: 253 | E10: 9.4 | F10: 49.9 | G10: 3.7 | H10: 6.9 | I10: TACO 4ª ed.; pelo nome | J10: Fatia de 25 g é aproximação; conferir marca | K10: https://nepa.unicamp.br/wp-content/uploads/sites/27/2023/10/taco_4_edicao_ampliada_e_revisada.pdf | L10: =IF(A10="","",IF(AND(ISNUMBER(C10),C10>0,COUNT(D10:H10)=5),"OK","Rever macros")) | M10: fatia | N10: 25 | O10: Referência cadastrada — não auditada nesta revisão
A11: Banana nanica | B11: g | C11: 100 | D11: 92 | E11: 1.4 | F11: 23.8 | G11: 0.1 | H11: 1.9 | I11: TACO 4ª ed.; pelo nome | J11: Sem casca | K11: https://nepa.unicamp.br/wp-content/uploads/sites/27/2023/10/taco_4_edicao_ampliada_e_revisada.pdf | L11: =IF(A11="","",IF(AND(ISNUMBER(C11),C11>0,COUNT(D11:H11)=5),"OK","Rever macros")) | O11: Referência cadastrada — não auditada nesta revisão
A12: Aveia em flocos | B12: g | C12: 100 | D12: 394 | E12: 13.9 | F12: 66.6 | G12: 8.5 | H12: 9.1 | I12: TACO 4ª ed.; pelo nome | J12: Peso seco | K12: https://nepa.unicamp.br/wp-content/uploads/sites/27/2023/10/taco_4_edicao_ampliada_e_revisada.pdf | L12: =IF(A12="","",IF(AND(ISNUMBER(C12),C12>0,COUNT(D12:H12)=5),"OK","Rever macros")) | O12: Referência cadastrada — não auditada nesta revisão
A13: Leite integral (estimativa) | B13: ml | C13: 100 | D13: 61 | E13: 3.2 | F13: 4.7 | G13: 3.3 | H13: 0 | I13: Estimativa genérica | J13: Substituir pelos valores do rótulo | K13: Conferir rótulo / estimativa | L13: =IF(A13="","",IF(AND(ISNUMBER(C13),C13>0,COUNT(D13:H13)=5),"OK","Rever macros")) | O13: Estimativa — conferir rótulo
A14: Whey (rótulo a conferir) | B14: g | C14: 30 | D14: 120 | E14: 23 | F14: 4 | G14: 1.3 | H14: 0 | I14: Estimativa genérica | J14: 30 g de pó. Atualizar ao comprar | K14: Conferir rótulo / estimativa | L14: =IF(A14="","",IF(AND(ISNUMBER(C14),C14>0,COUNT(D14:H14)=5),"OK","Rever macros")) | O14: Estimativa — conferir rótulo
A15: Azeite | B15: g | C15: 100 | D15: 884 | E15: 0 | F15: 0 | G15: 100 | H15: 0 | I15: TACO 4ª ed.; pelo nome | J15: Contabilizar gordura usada no preparo | K15: https://nepa.unicamp.br/wp-content/uploads/sites/27/2023/10/taco_4_edicao_ampliada_e_revisada.pdf | L15: =IF(A15="","",IF(AND(ISNUMBER(C15),C15>0,COUNT(D15:H15)=5),"OK","Rever macros")) | O15: Referência cadastrada — não auditada nesta revisão
A16: Cenoura cozida | B16: g | C16: 100 | D16: 30 | E16: 0.8 | F16: 6.7 | G16: 0.2 | H16: 2.6 | I16: TACO 4ª ed.; pelo nome | J16: Exemplo de legume; substituir pelo consumido | K16: https://nepa.unicamp.br/wp-content/uploads/sites/27/2023/10/taco_4_edicao_ampliada_e_revisada.pdf | L16: =IF(A16="","",IF(AND(ISNUMBER(C16),C16>0,COUNT(D16:H16)=5),"OK","Rever macros")) | O16: Referência cadastrada — não auditada nesta revisão
A17: Laranja pera | B17: g | C17: 100 | D17: 37 | E17: 1 | F17: 8.9 | G17: 0.1 | H17: 0.8 | I17: TACO 4ª ed.; pelo nome | J17: Parte comestível | K17: https://nepa.unicamp.br/wp-content/uploads/sites/27/2023/10/taco_4_edicao_ampliada_e_revisada.pdf | L17: =IF(A17="","",IF(AND(ISNUMBER(C17),C17>0,COUNT(D17:H17)=5),"OK","Rever macros")) | O17: Referência cadastrada — não auditada nesta revisão
A18: Batata inglesa cozida | B18: g | C18: 100 | D18: 52 | E18: 1.2 | F18: 11.9 | G18: 0 | H18: 1.3 | I18: TACO 4ª ed.; pelo nome | J18: Sem óleo | K18: https://nepa.unicamp.br/wp-content/uploads/sites/27/2023/10/taco_4_edicao_ampliada_e_revisada.pdf | L18: =IF(A18="","",IF(AND(ISNUMBER(C18),C18>0,COUNT(D18:H18)=5),"OK","Rever macros")) | O18: Referência cadastrada — não auditada nesta revisão
A19: Batata doce cozida | B19: g | C19: 100 | D19: 77 | E19: 0.6 | F19: 18.4 | G19: 0.1 | H19: 2.2 | I19: TACO 4ª ed.; pelo nome | J19: Sem óleo | K19: https://nepa.unicamp.br/wp-content/uploads/sites/27/2023/10/taco_4_edicao_ampliada_e_revisada.pdf | L19: =IF(A19="","",IF(AND(ISNUMBER(C19),C19>0,COUNT(D19:H19)=5),"OK","Rever macros")) | O19: Referência cadastrada — não auditada nesta revisão
A20: Iogurte natural | B20: g | C20: 100 | D20: 51 | E20: 4.1 | F20: 1.9 | G20: 3 | H20: 0 | I20: TACO 4ª ed.; pelo nome | J20: Conferir rótulo do produto | K20: https://nepa.unicamp.br/wp-content/uploads/sites/27/2023/10/taco_4_edicao_ampliada_e_revisada.pdf | L20: =IF(A20="","",IF(AND(ISNUMBER(C20),C20>0,COUNT(D20:H20)=5),"OK","Rever macros")) | O20: Referência cadastrada — não auditada nesta revisão
A21: Queijo minas frescal | B21: g | C21: 100 | D21: 264 | E21: 17.4 | F21: 3.2 | G21: 20.2 | H21: 0 | I21: TACO 4ª ed.; pelo nome | J21: Pesar porção | K21: https://nepa.unicamp.br/wp-content/uploads/sites/27/2023/10/taco_4_edicao_ampliada_e_revisada.pdf | L21: =IF(A21="","",IF(AND(ISNUMBER(C21),C21>0,COUNT(D21:H21)=5),"OK","Rever macros")) | O21: Referência cadastrada — não auditada nesta revisão
A22: Clara de ovo cozida | B22: g | C22: 100 | D22: 59 | E22: 13.4 | F22: 0 | G22: 0.1 | H22: 0 | I22: TACO 4ª ed.; pelo nome | J22: Sem gema | K22: https://nepa.unicamp.br/wp-content/uploads/sites/27/2023/10/taco_4_edicao_ampliada_e_revisada.pdf | L22: =IF(A22="","",IF(AND(ISNUMBER(C22),C22>0,COUNT(D22:H22)=5),"OK","Rever macros")) | O22: Referência cadastrada — não auditada nesta revisão
... A61: Macarrão integral cozido | B61: g | C61: 100 | D61: 124 | E61: 5.3 | F61: 26.5 | G61: 0.5 | H61: 3.9 | I61: Estimativa genérica | J61: Pesar cozido; molho à parte | K61: Conferir rótulo / estimativa | L61: =IF(A61="","",IF(AND(ISNUMBER(C61),C61>0,COUNT(D61:H61)=5),"OK","Rever macros")) | O61: Estimativa — conferir rótulo
A62: Pão francês | B62: g | C62: 100 | D62: 300 | E62: 8 | F62: 58.6 | G62: 3.1 | H62: 2.3 | I62: TACO 4ª ed.; pelo nome | J62: 1 unidade média tem cerca de 50 g | K62: Tabela TACO Unicamp | L62: =IF(A62="","",IF(AND(ISNUMBER(C62),C62>0,COUNT(D62:H62)=5),"OK","Rever macros")) | M62: un | N62: 50 | O62: Referência cadastrada — não auditada nesta revisão
A63: Pão de forma tradicional | B63: g | C63: 100 | D63: 265 | E63: 8.4 | F63: 51.8 | G63: 2.4 | H63: 2.5 | I63: TACO 4ª ed.; pelo nome | J63: Fatia cerca de 25 g | K63: Tabela TACO Unicamp | L63: =IF(A63="","",IF(AND(ISNUMBER(C63),C63>0,COUNT(D63:H63)=5),"OK","Rever macros")) | M63: fatia | N63: 25 | O63: Referência cadastrada — não auditada nesta revisão
A64: Goma de tapioca hidratada | B64: g | C64: 100 | D64: 242 | E64: 0.3 | F64: 59.8 | G64: 0.2 | H64: 0.6 | I64: TACO 4ª ed.; pelo nome | J64: Pesar a massa crua antes de assar | K64: Tabela TACO Unicamp | L64: =IF(A64="","",IF(AND(ISNUMBER(C64),C64>0,COUNT(D64:H64)=5),"OK","Rever macros")) | O64: Referência cadastrada — não auditada nesta revisão
A65: Cuscuz de milho cozido | B65: g | C65: 100 | D65: 113 | E65: 2.2 | F65: 25.3 | G65: 0.7 | H65: 1.8 | I65: TACO 4ª ed.; pelo nome | J65: Pesar pronto; manteiga à parte | K65: Tabela TACO Unicamp | L65: =IF(A65="","",IF(AND(ISNUMBER(C65),C65>0,COUNT(D65:H65)=5),"OK","Rever macros")) | O65: Referência cadastrada — não auditada nesta revisão
A66: Milho verde cozido | B66: g | C66: 100 | D66: 138 | E66: 3.3 | F66: 28.6 | G66: 2.4 | H66: 3.9 | I66: TACO 4ª ed.; pelo nome | J66: Pesar grãos debulhados | K66: Tabela TACO Unicamp | L66: =IF(A66="","",IF(AND(ISNUMBER(C66),C66>0,COUNT(D66:H66)=5),"OK","Rever macros")) | O66: Referência cadastrada — não auditada nesta revisão
