Workbook

Sheet Hoje
A2: Projeto Breno: registro rápido
A3: Use o menu Projeto. Salve o que souber; informações faltantes não impedem retomar o acompanhamento.
A4: Ação rápida | B4: —
A5: Data | B5: =TODAY() -> 46293 | D5: Status | E5: Revisão 3.0 validada: fichas, unidades e volume dos work sets.
A7: Peso kg | D7: Sono h | G7: Passos | J7: Cardio min
A9: Registrou tudo? | B9: Não | D9: Muay Thai? | E9: Não | G9: Cintura cm | J9: Fome 1–5
A11: Cansaço 1–5 | D11: Observações
A14: Favorita | D14: Porções | E14: 1 | G14: Refeição | H14: Café da manhã
A16: Alimento | D16: Quantidade | G16: Medição | H16: Estimada | J16: Unidade →
A17: Escolha a unidade: 2 un de ovo ≠ 2 g. Conversões caseiras são estimadas.
A18: Copiar da data | D18: Refeição ou Todas | E18: Todas
A20: Refeição sem cálculo
A23: Sessão | D23: Fase | E23: Regular | G23: Ficha carregada
A24: Carga: siga o critério do cadastro de Exercícios. Preparação em cinza; work sets em verde.
A26: Exercício | B26: Aquec. kg | C26: Aquec. reps | D26: Feeder kg | E26: Feeder reps | F26: Work 1 kg | G26: Work 1 reps | H26: Work 2 kg | I26: Work 2 reps | J26: RIR work 2 | K26: Dor 0–10 | L26: Observação | M26: RIR work 1
A39: RIR = repetições em reserva. Informe para cada work set; 0 é um registro válido.
A40: Feeder: 6 reps longe da falha. Trabalho: 2×6–10, 0–1 RIR. Apenas work sets entram nos indicadores.
A42: Meta × realizado do dia
A43: Indicador | B43: Realizado | C43: Meta | D43: Comparação | E43: Status
A44: kcal | B44: =IF(COUNTIF('Alimentação'!$A:$A,$B$5)=0,"",SUMIFS('Alimentação'!$F:$F,'Alimentação'!$A:$A,$B$5)) | C44: =IF(COUNTIFS('Diário'!$A:$A,$B$5,'Diário'!$M:$M,">0")=0,"",SUMIFS('Diário'!$M:$M,'Diário'!$A:$A,$B$5)) | D44: =IF(NOT(ISNUMBER(B44)),"Sem registro",TEXT(B44,"0")&" / "&IF(ISNUMBER(C44),TEXT(C44,"0"),"meta pendente")) -> Sem registro | E44: =IF(COUNTIF('Alimentação'!$A$6:$A1000,$B$5)=0,"Sem registro",IF(COUNTIFS('Diário'!$A$6:$A1000,$B$5,'Diário'!$G$6:$G1000,"Sim")=0,"Parcial — em andamento",IF(SUMIFS('Diário'!$AG$6:$AG1000,'Diário'!$A$6:$A1000,$B$5)>0,"Completo — cálculo parcial",IF(OR(NOT(ISNUMBER(B44)),NOT(ISNUMBER(C44))),"Pendente",IF(ABS(B44/C44-1)<=SUMIFS('Diário'!$T:$T,'Diário'!$A:$A,$B$5),"Na faixa",IF(ABS(B44/C44-1)<=0.2,"Próximo","Distante")))))) -> Sem registro
A45: Proteína g | B45: =IF(COUNTIF('Alimentação'!$A:$A,$B$5)=0,"",SUMIFS('Alimentação'!$G:$G,'Alimentação'!$A:$A,$B$5)) | C45: =IF(COUNTIFS('Diário'!$A:$A,$B$5,'Diário'!$N:$N,">0")=0,"",SUMIFS('Diário'!$N:$N,'Diário'!$A:$A,$B$5)) | D45: =IF(NOT(ISNUMBER(B45)),"Sem registro",TEXT(B45,"0")&" / "&IF(ISNUMBER(C45),TEXT(C45,"0"),"meta pendente")) -> Sem registro | E45: =IF(COUNTIF('Alimentação'!$A$6:$A1000,$B$5)=0,"Sem registro",IF(COUNTIFS('Diário'!$A$6:$A1000,$B$5,'Diário'!$G$6:$G1000,"Sim")=0,"Parcial — em andamento",IF(SUMIFS('Diário'!$AG$6:$AG1000,'Diário'!$A$6:$A1000,$B$5)>0,"Completo — cálculo parcial",IF(OR(NOT(ISNUMBER(B45)),NOT(ISNUMBER(C45))),"Pendente",IF(AND(B45>=SUMIFS('Diário'!$R:$R,'Diário'!$A:$A,$B$5),B45<=SUMIFS('Diário'!$S:$S,'Diário'!$A:$A,$B$5)),"Na faixa",IF(ABS(B45/C45-1)<=0.2,"Próximo","Distante")))))) -> Sem registro
A46: Gordura g | B46: =IF(COUNTIF('Alimentação'!$A:$A,$B$5)=0,"",SUMIFS('Alimentação'!$I:$I,'Alimentação'!$A:$A,$B$5)) | C46: =IF(COUNTIFS('Diário'!$A:$A,$B$5,'Diário'!$O:$O,">0")=0,"",SUMIFS('Diário'!$O:$O,'Diário'!$A:$A,$B$5)) | D46: =IF(NOT(ISNUMBER(B46)),"Sem registro",TEXT(B46,"0")&" / "&IF(ISNUMBER(C46),TEXT(C46,"0"),"meta pendente")) -> Sem registro | E46: =IF(COUNTIF('Alimentação'!$A$6:$A1000,$B$5)=0,"Sem registro",IF(COUNTIFS('Diário'!$A$6:$A1000,$B$5,'Diário'!$G$6:$G1000,"Sim")=0,"Parcial — em andamento",IF(SUMIFS('Diário'!$AG$6:$AG1000,'Diário'!$A$6:$A1000,$B$5)>0,"Completo — cálculo parcial",IF(OR(NOT(ISNUMBER(B46)),NOT(ISNUMBER(C46))),"Pendente",IF(ABS(B46/C46-1)<=SUMIFS('Diário'!$U:$U,'Diário'!$A:$A,$B$5),"Na faixa",IF(ABS(B46/C46-1)<=0.2,"Próximo","Distante")))))) -> Sem registro
A48: Configuração e revisões
A50: Upper → Lower → Full Body. Organize os dias junto ao Muay Thai.
A51: Menu Projeto: carregar → registrar → salvar parcial ou concluir. Retome registros sem preencher dias atrasados.

Sheet Painel
A2: Projeto Breno: decisões da semana
A5: Semana iniciada em | B5: =Hoje!B5-WEEKDAY(Hoje!B5,2)+1 -> 46293
A7: Peso médio kg | B7: =IF(COUNTIFS(Semanas!$A:$A,$B$5,Semanas!$D:$D,">=-100000")=0,"",SUMIFS(Semanas!$D:$D,Semanas!$A:$A,$B$5))
A8: Mudança vs semana anterior kg | B8: =IF(COUNTIFS(Semanas!$A:$A,$B$5,Semanas!$E:$E,">=-100000")=0,"",SUMIFS(Semanas!$E:$E,Semanas!$A:$A,$B$5))
A9: Cintura cm | B9: =IF(COUNTIFS(Semanas!$A:$A,$B$5,Semanas!$F:$F,">=-100000")=0,"",SUMIFS(Semanas!$F:$F,Semanas!$A:$A,$B$5))
A10: kcal — dias completos | B10: =IF(COUNTIFS(Semanas!$A:$A,$B$5,Semanas!$G:$G,">=-100000")=0,"",SUMIFS(Semanas!$G:$G,Semanas!$A:$A,$B$5))
A11: Proteína média g | B11: =IF(COUNTIFS(Semanas!$A:$A,$B$5,Semanas!$H:$H,">=-100000")=0,"",SUMIFS(Semanas!$H:$H,Semanas!$A:$A,$B$5))
A12: Gordura média g | B12: =IF(COUNTIFS(Semanas!$A:$A,$B$5,Semanas!$I:$I,">=-100000")=0,"",SUMIFS(Semanas!$I:$I,Semanas!$A:$A,$B$5))
A13: Dias completos com cálculo | B13: =IF(COUNTIFS(Semanas!$A:$A,$B$5,Semanas!$J:$J,">=-100000")=0,"",SUMIFS(Semanas!$J:$J,Semanas!$A:$A,$B$5))
A14: Aderência calórica | B14: =IF(COUNTIFS(Semanas!$A:$A,$B$5,Semanas!$K:$K,">=-100000")=0,"",SUMIFS(Semanas!$K:$K,Semanas!$A:$A,$B$5))
A15: Aderência proteína | B15: =IF(COUNTIFS(Semanas!$A:$A,$B$5,Semanas!$L:$L,">=-100000")=0,"",SUMIFS(Semanas!$L:$L,Semanas!$A:$A,$B$5))
A16: Treinos realizados | B16: =IF(COUNTIFS(Semanas!$A:$A,$B$5,Semanas!$M:$M,">=-100000")=0,"",SUMIFS(Semanas!$M:$M,Semanas!$A:$A,$B$5))
A17: Meta semanal de treinos | B17: =IF(COUNTIFS(Semanas!$A:$A,$B$5,Semanas!$N:$N,">=-100000")=0,"",SUMIFS(Semanas!$N:$N,Semanas!$A:$A,$B$5))
A18: Passos médios | B18: =IF(COUNTIFS(Semanas!$A:$A,$B$5,Semanas!$O:$O,">=-100000")=0,"",SUMIFS(Semanas!$O:$O,Semanas!$A:$A,$B$5))
A19: Cardio min | B19: =IF(COUNTIFS(Semanas!$A:$A,$B$5,Semanas!$P:$P,">=-100000")=0,"",SUMIFS(Semanas!$P:$P,Semanas!$A:$A,$B$5))
A20: Sono médio h | B20: =IF(COUNTIFS(Semanas!$A:$A,$B$5,Semanas!$Q:$Q,">=-100000")=0,"",SUMIFS(Semanas!$Q:$Q,Semanas!$A:$A,$B$5))
A21: Muay Thai | B21: =IF(COUNTIFS(Semanas!$A:$A,$B$5,Semanas!$R:$R,">=-100000")=0,"",SUMIFS(Semanas!$R:$R,Semanas!$A:$A,$B$5))
A22: Cobertura de pesagens | B22: =IF(COUNTIFS(Semanas!$A:$A,$B$5,Semanas!$C:$C,">=-100000")=0,"",SUMIFS(Semanas!$C:$C,Semanas!$A:$A,$B$5))
A25: Leitura para revisão
B26: =IF(B13="","Sem histórico alimentar. Registre o que souber.","Médias calculadas com "&B13&" dias completos e com cálculo; não representam os dias ausentes.") -> Sem histórico alimentar. Registre o que souber.
A28: Semana parcial | B28: =IF($B$5+6>=TODAY(),"Sim. Não comparar contagens com uma semana completa.","Não.") -> Sim. Não comparar contagens com uma semana completa.
A30: Metas históricas | B30: Aderência usa a meta gravada em cada dia.
A32: Faixas usadas | B32: kcal ±5%; gordura ±15%; proteína pela faixa individual.
A34: Próxima ação | B34: Revisar tolerância à musculação junto do Muay Thai.
A36: Cobertura alimentar | B36: {=IFERROR(INDEX(Semanas!$V$6:$V1000,MATCH(B5,Semanas!$A$6:$A1000,0)),"Sem registros nesta semana")} -> Sem registros nesta semana
A38: Itens sem cálculo | B38: {=IFERROR(INDEX(Semanas!$U$6:$U1000,MATCH(B5,Semanas!$A$6:$A1000,0)),0)} -> 0

Sheet Progressão
A2: Progressão por exercício
A5: Exercício
A7: Compare apenas work sets do mesmo exercício e critério de carga. Atualize pelo menu Projeto.
A9: Data | B9: Ficha | C9: Exercício | D9: Work 1 kg | E9: Work 1 reps | F9: Work 2 kg | G9: Work 2 reps | H9: Volume work | I9: Work sets | J9: RIR work 1 | K9: RIR work 2 | L9: Sessão | M9: Estado | N9: Leitura
A33: Compare mesmo equipamento, amplitude e RIR. O volume é carga × repetições, não uma medida isolada de progresso.

Sheet Macros e perfil
A2: Projeto Breno : perfil e referências iniciais
A3: Para mudar metas após o início, use Nova meta na tela Hoje. O histórico preserva os dias já salvos.
A5: Parâmetro | B5: Valor editável | C5: Unidade / critério | D5: Origem e pendência
A6: Nome | B6: Breno | D6: Informado no chat
A7: Idade | B7: 24 | C7: anos | D7: 24 no cadastro; confirmar quando oportuno.
A8: Altura | B8: 1.79 | C8: m | D8: Informado
A9: Peso inicial | B9: 67 | C9: kg | D9: Informado; não é medição datada
A10: Início do acompanhamento | B10: 46286 | C10: data | D10: Data do primeiro registro. O histórico usa datas reais.
A11: Meta de musculação | B11: 3 | C11: sessões/semana | D11: Ajustar se a recuperação exigir
A12: Muay Thai | B12: 2 | C12: sessões/semana | D12: Dias exatos a confirmar
A13: Cardio extra | B13: 0 | C13: sessões/semana | D13: Sem cardio extra inicialmente
A14: Proteína de referência | B14: 140 | C14: g/dia | D14: Referência inicial. Metas vigentes e alterações ficam em Histórico de metas.
A15: Proteína faixa inferior | B15: 135 | C15: g/dia | D15: Faixa discutida no chat
A16: Proteína faixa superior | B16: 145 | C16: g/dia | D16: Faixa discutida no chat
A17: Energia de referência | B17: 2400 | C17: kcal/dia | D17: Referência inicial; novas metas devem ser criadas pelo botão Nova meta.
A18: Gordura de referência | B18: 65 | C18: g/dia | D18: Faixa discutida: 60–70 g/dia
A19: Carboidrato de referência | B19: =IF(OR(B17="",B18="",B14=""),"",(B17-4*B14-9*B18)/4) -> 313.75 | C19: g/dia | D19: Calculado pelo saldo de energia após proteína e gordura
A20: Proteína / peso inicial | B20: =IF(OR(B9="",B14=""),"",B14/B9) -> 2.0895522 | C20: g/kg/dia | D20: Calculado a partir da referência, sem estimar gasto
A21: Creatina planejada | C21: g/dia | D21: Uso não confirmado no chat do Breno
A22: Início da creatina | C22: data | D22: Ajuda a interpretar mudanças de água corporal
A23: Saúde | B23: Não informado | D23: Relato, não avaliação clínica
A24: Tabagismo | B24: Não informado | D24: Não informado para Breno.
A25: Rotina | B25: Pouca caminhada | D25: Rotina individual do Breno.
A26: Objetivo | B26: Recomposição corporal | D26: Ganhar músculo e acompanhar cintura, desempenho e recuperação
A27: Status da ficha | B27: F002 — vigente desde 28/09/2026 | D27: Luan revisa exercícios, séries e recuperação
A28: Revisor | B28: Luan | D28: Preencher data de revisão na aba Revisões
A29: Versão | B29: 3.0 — Google Sheets / work sets | D29: Criada em 15/09/2026
A30: Semanas disponíveis | B30: Expansível | C30: semanas | D30: Tabelas crescem ao salvar. Cadastros: use Tab na última célula da tabela.
A33: Total da dieta base | B33: Calculado | C33: Unidade | D33: Leitura
A34: Energia proposta | B34: ='Dieta base'!E31 -> 2440.7 | C34: kcal | D34: Comparar com referência inicial de 2.400 kcal.
A35: Proteína proposta | B35: ='Dieta base'!F31 -> 144.90667 | C35: g
A36: Carboidrato proposto | B36: ='Dieta base'!G31 -> 314.21333 | C36: g
A37: Gordura proposta | B37: ='Dieta base'!H31 -> 69.523333 | C37: g
A38: Fibra proposta | B38: ='Dieta base'!I31 -> 44.39 | C38: g | D38: Aumentar fibras gradualmente conforme tolerância digestiva.

Sheet Ficha de treino
A2: Projeto Breno — ficha vigente F002
A3: Aquecimento e feeder ficam separados. Apenas as duas work sets entram no volume e na progressão.
A5: Sessão | B5: Exercício | C5: Grupo principal | D5: Work sets adaptação | E5: Work sets regular | F5: Reps work mín. | G5: Reps work máx. | H5: RIR work adaptação máx. | I5: RIR work regular máx. | J5: Descanso s | K5: Alternativa | L5: Status do plano | M5: Tipos de série
A6: Upper | B6: Supino inclinado | C6: Peito | D6: 2 | E6: 2 | F6: 6 | G6: 10 | H6: 1 | I6: 1 | J6: 150 | K6: Supino inclinado máquina | L6: Confirmado por Luan | M6: 1 aquecimento + 1 feeder de 6 reps longe da falha + 2 work sets de 6–10 reps, 0–1 RIR.
A7: Upper | B7: Puxada aberta | C7: Costas | D7: 2 | E7: 2 | F7: 6 | G7: 10 | H7: 1 | I7: 1 | J7: 150 | L7: Confirmado por Luan | M7: 1 aquecimento + 1 feeder de 6 reps longe da falha + 2 work sets de 6–10 reps, 0–1 RIR.
A8: Upper | B8: Remada baixa com triângulo | C8: Costas | D8: 2 | E8: 2 | F8: 6 | G8: 10 | H8: 1 | I8: 1 | J8: 150 | L8: Confirmado por Luan | M8: 1 aquecimento + 1 feeder de 6 reps longe da falha + 2 work sets de 6–10 reps, 0–1 RIR.
A9: Upper | B9: Supino reto na máquina | C9: Peito | D9: 2 | E9: 2 | F9: 6 | G9: 10 | H9: 1 | I9: 1 | J9: 150 | L9: Confirmado por Luan | M9: 1 aquecimento + 1 feeder de 6 reps longe da falha + 2 work sets de 6–10 reps, 0–1 RIR.
A10: Upper | B10: Elevação lateral | C10: Ombros | D10: 2 | E10: 2 | F10: 6 | G10: 10 | H10: 1 | I10: 1 | J10: 120 | L10: Confirmado por Luan | M10: 1 aquecimento + 1 feeder de 6 reps longe da falha + 2 work sets de 6–10 reps, 0–1 RIR.
A11: Upper | B11: Crucifixo inverso | C11: Ombros | D11: 2 | E11: 2 | F11: 6 | G11: 10 | H11: 1 | I11: 1 | J11: 120 | K11: Peck deck reverso | L11: Confirmado por Luan | M11: 1 aquecimento + 1 feeder de 6 reps longe da falha + 2 work sets de 6–10 reps, 0–1 RIR.
A12: Upper | B12: Rosca Scott | C12: Bíceps | D12: 2 | E12: 2 | F12: 6 | G12: 10 | H12: 1 | I12: 1 | J12: 120 | L12: Confirmado por Luan | M12: 1 aquecimento + 1 feeder de 6 reps longe da falha + 2 work sets de 6–10 reps, 0–1 RIR.
A13: Upper | B13: Tríceps na corda | C13: Tríceps | D13: 2 | E13: 2 | F13: 6 | G13: 10 | H13: 1 | I13: 1 | J13: 120 | L13: Confirmado por Luan | M13: 1 aquecimento + 1 feeder de 6 reps longe da falha + 2 work sets de 6–10 reps, 0–1 RIR.
A14: Lower | B14: Agachamento orientado | C14: Quadríceps | D14: 2 | E14: 2 | F14: 6 | G14: 10 | H14: 1 | I14: 1 | J14: 150 | L14: Confirmado por Luan | M14: 1 aquecimento + 1 feeder de 6 reps longe da falha + 2 work sets de 6–10 reps, 0–1 RIR.
A15: Lower | B15: Leg press | C15: Quadríceps | D15: 2 | E15: 2 | F15: 6 | G15: 10 | H15: 1 | I15: 1 | J15: 150 | L15: Confirmado por Luan | M15: 1 aquecimento + 1 feeder de 6 reps longe da falha + 2 work sets de 6–10 reps, 0–1 RIR.
A16: Lower | B16: Stiff orientado | C16: Posteriores | D16: 2 | E16: 2 | F16: 6 | G16: 10 | H16: 1 | I16: 1 | J16: 150 | L16: Confirmado por Luan | M16: 1 aquecimento + 1 feeder de 6 reps longe da falha + 2 work sets de 6–10 reps, 0–1 RIR.
A17: Lower | B17: Mesa flexora | C17: Posteriores | D17: 2 | E17: 2 | F17: 6 | G17: 10 | H17: 1 | I17: 1 | J17: 150 | L17: Confirmado por Luan | M17: 1 aquecimento + 1 feeder de 6 reps longe da falha + 2 work sets de 6–10 reps, 0–1 RIR.
A18: Lower | B18: Panturrilha em pé | C18: Panturrilhas | D18: 2 | E18: 2 | F18: 6 | G18: 10 | H18: 1 | I18: 1 | J18: 120 | K18: Panturrilha sentado | L18: Confirmado por Luan | M18: 1 aquecimento + 1 feeder de 6 reps longe da falha + 2 work sets de 6–10 reps, 0–1 RIR.
A19: Lower | B19: Abdominal na polia | C19: Abdômen | D19: 2 | E19: 2 | F19: 6 | G19: 10 | H19: 1 | I19: 1 | J19: 120 | L19: Confirmado por Luan | M19: 1 aquecimento + 1 feeder de 6 reps longe da falha + 2 work sets de 6–10 reps, 0–1 RIR.
A20: Full Body | B20: Leg press | C20: Quadríceps | D20: 2 | E20: 2 | F20: 6 | G20: 10 | H20: 1 | I20: 1 | J20: 150 | L20: Confirmado por Luan | M20: 1 aquecimento + 1 feeder de 6 reps longe da falha + 2 work sets de 6–10 reps, 0–1 RIR.
A21: Full Body | B21: Supino inclinado com halteres | C21: Peito | D21: 2 | E21: 2 | F21: 6 | G21: 10 | H21: 1 | I21: 1 | J21: 150 | L21: Confirmado por Luan | M21: 1 aquecimento + 1 feeder de 6 reps longe da falha + 2 work sets de 6–10 reps, 0–1 RIR.
A22: Full Body | B22: Puxada aberta | C22: Costas | D22: 2 | E22: 2 | F22: 6 | G22: 10 | H22: 1 | I22: 1 | J22: 150 | L22: Confirmado por Luan | M22: 1 aquecimento + 1 feeder de 6 reps longe da falha + 2 work sets de 6–10 reps, 0–1 RIR.
A23: Full Body | B23: Remada com apoio | C23: Costas | D23: 2 | E23: 2 | F23: 6 | G23: 10 | H23: 1 | I23: 1 | J23: 150 | K23: Máquina disponível; confirmar execução com Luan | L23: Confirmado por Luan | M23: 1 aquecimento + 1 feeder de 6 reps longe da falha + 2 work sets de 6–10 reps, 0–1 RIR.
A24: Full Body | B24: Elevação lateral | C24: Ombros | D24: 2 | E24: 2 | F24: 6 | G24: 10 | H24: 1 | I24: 1 | J24: 120 | L24: Confirmado por Luan | M24: 1 aquecimento + 1 feeder de 6 reps longe da falha + 2 work sets de 6–10 reps, 0–1 RIR.
A25: Full Body | B25: Crucifixo inverso | C25: Ombros | D25: 2 | E25: 2 | F25: 6 | G25: 10 | H25: 1 | I25: 1 | J25: 120 | K25: Peck deck reverso | L25: Confirmado por Luan | M25: 1 aquecimento + 1 feeder de 6 reps longe da falha + 2 work sets de 6–10 reps, 0–1 RIR.
A26: Full Body | B26: Rosca alternada | C26: Bíceps | D26: 2 | E26: 2 | F26: 6 | G26: 10 | H26: 1 | I26: 1 | J26: 120 | L26: Confirmado por Luan | M26: 1 aquecimento + 1 feeder de 6 reps longe da falha + 2 work sets de 6–10 reps, 0–1 RIR.
A27: Full Body | B27: Tríceps na corda | C27: Tríceps | D27: 2 | E27: 2 | F27: 6 | G27: 10 | H27: 1 | I27: 1 | J27: 120 | L27: Confirmado por Luan | M27: 1 aquecimento + 1 feeder de 6 reps longe da falha + 2 work sets de 6–10 reps, 0–1 RIR.

Sheet Registro de treino
A2: Registro por exercício e sessão
A3: Histórico: aquecimento e feeder preservados; volume calculado somente com Work 1 + Work 2. Salvar parcial permite retomar.
A5: Data | B5: Sessão | C5: Exercício | D5: Equipamento / carga | E5: Aquecimento kg | F5: Aquecimento reps | G5: Feeder kg | H5: Feeder reps | I5: Work 1 kg | J5: Work 1 reps | K5: Work 2 kg | L5: Work 2 reps | M5: Work sets realizadas | N5: Volume work kg×reps | O5: RIR work 2 | P5: Dor 0–10 | Q5: Observação | R5: Ficha | S5: Work sets prescritas | T5: Reps work mín | U5: Reps work máx | V5: Fase | W5: ID sessão | X5: RIR work 1 | Y5: Estado sessão | Z5: Modelo de séries

Sheet Dieta base
A2: Dieta base com porções revisáveis
A3: Base do chat ajustada nas porções para aproximar 2.400 kcal e a meta proteica. Ver alterações em Revisões.
A5: Refeição | B5: Alimento | C5: Quantidade | D5: Unidade | E5: kcal | F5: Proteína g | G5: Carboidrato g | H5: Gordura g | I5: Fibra g | J5: Adaptação / observação
A6: Café da manhã | B6: Ovo inteiro cru | C6: 150 | D6: =VLOOKUP(B6,Alimentos!$A:$L,2,FALSE) -> g | E6: =C6/VLOOKUP(B6,Alimentos!$A:$L,3,FALSE)*VLOOKUP(B6,Alimentos!$A:$L,4,FALSE) -> 214.5 | F6: =C6/VLOOKUP(B6,Alimentos!$A:$L,3,FALSE)*VLOOKUP(B6,Alimentos!$A:$L,5,FALSE) -> 19.5 | G6: =C6/VLOOKUP(B6,Alimentos!$A:$L,3,FALSE)*VLOOKUP(B6,Alimentos!$A:$L,6,FALSE) -> 2.4 | H6: =C6/VLOOKUP(B6,Alimentos!$A:$L,3,FALSE)*VLOOKUP(B6,Alimentos!$A:$L,7,FALSE) -> 13.35 | I6: =C6/VLOOKUP(B6,Alimentos!$A:$L,3,FALSE)*VLOOKUP(B6,Alimentos!$A:$L,8,FALSE) -> 0 | J6: 3 ovos médios; pesar cru na balança sem casca
A7: Café da manhã | B7: Margarina (estimativa) | C7: 5 | D7: =VLOOKUP(B7,Alimentos!$A:$L,2,FALSE) -> g | E7: =C7/VLOOKUP(B7,Alimentos!$A:$L,3,FALSE)*VLOOKUP(B7,Alimentos!$A:$L,4,FALSE) -> 36 | F7: =C7/VLOOKUP(B7,Alimentos!$A:$L,3,FALSE)*VLOOKUP(B7,Alimentos!$A:$L,5,FALSE) -> 0 | G7: =C7/VLOOKUP(B7,Alimentos!$A:$L,3,FALSE)*VLOOKUP(B7,Alimentos!$A:$L,6,FALSE) -> 0 | H7: =C7/VLOOKUP(B7,Alimentos!$A:$L,3,FALSE)*VLOOKUP(B7,Alimentos!$A:$L,7,FALSE) -> 4 | I7: =C7/VLOOKUP(B7,Alimentos!$A:$L,3,FALSE)*VLOOKUP(B7,Alimentos!$A:$L,8,FALSE) -> 0 | J7: Gordura de preparo dos ovos na frigideira
A8: Café da manhã | B8: Pão integral | C8: 50 | D8: =VLOOKUP(B8,Alimentos!$A:$L,2,FALSE) -> g | E8: =C8/VLOOKUP(B8,Alimentos!$A:$L,3,FALSE)*VLOOKUP(B8,Alimentos!$A:$L,4,FALSE) -> 126.5 | F8: =C8/VLOOKUP(B8,Alimentos!$A:$L,3,FALSE)*VLOOKUP(B8,Alimentos!$A:$L,5,FALSE) -> 4.7 | G8: =C8/VLOOKUP(B8,Alimentos!$A:$L,3,FALSE)*VLOOKUP(B8,Alimentos!$A:$L,6,FALSE) -> 24.95 | H8: =C8/VLOOKUP(B8,Alimentos!$A:$L,3,FALSE)*VLOOKUP(B8,Alimentos!$A:$L,7,FALSE) -> 1.85 | I8: =C8/VLOOKUP(B8,Alimentos!$A:$L,3,FALSE)*VLOOKUP(B8,Alimentos!$A:$L,8,FALSE) -> 3.45 | J8: Cerca de 2 fatias
A9: Café da manhã | B9: Banana nanica | C9: 100 | D9: =VLOOKUP(B9,Alimentos!$A:$L,2,FALSE) -> g | E9: =C9/VLOOKUP(B9,Alimentos!$A:$L,3,FALSE)*VLOOKUP(B9,Alimentos!$A:$L,4,FALSE) -> 92 | F9: =C9/VLOOKUP(B9,Alimentos!$A:$L,3,FALSE)*VLOOKUP(B9,Alimentos!$A:$L,5,FALSE) -> 1.4 | G9: =C9/VLOOKUP(B9,Alimentos!$A:$L,3,FALSE)*VLOOKUP(B9,Alimentos!$A:$L,6,FALSE) -> 23.8 | H9: =C9/VLOOKUP(B9,Alimentos!$A:$L,3,FALSE)*VLOOKUP(B9,Alimentos!$A:$L,7,FALSE) -> 0.1 | I9: =C9/VLOOKUP(B9,Alimentos!$A:$L,3,FALSE)*VLOOKUP(B9,Alimentos!$A:$L,8,FALSE) -> 1.9
A10: Café da manhã | B10: Queijo minas frescal | C10: 20 | D10: =VLOOKUP(B10,Alimentos!$A:$L,2,FALSE) -> g | E10: =C10/VLOOKUP(B10,Alimentos!$A:$L,3,FALSE)*VLOOKUP(B10,Alimentos!$A:$L,4,FALSE) -> 52.8 | F10: =C10/VLOOKUP(B10,Alimentos!$A:$L,3,FALSE)*VLOOKUP(B10,Alimentos!$A:$L,5,FALSE) -> 3.48 | G10: =C10/VLOOKUP(B10,Alimentos!$A:$L,3,FALSE)*VLOOKUP(B10,Alimentos!$A:$L,6,FALSE) -> 0.64 | H10: =C10/VLOOKUP(B10,Alimentos!$A:$L,3,FALSE)*VLOOKUP(B10,Alimentos!$A:$L,7,FALSE) -> 4.04 | I10: =C10/VLOOKUP(B10,Alimentos!$A:$L,3,FALSE)*VLOOKUP(B10,Alimentos!$A:$L,8,FALSE) -> 0
A11: Café da manhã | B11: Leite integral (estimativa) | C11: 200 | D11: =VLOOKUP(B11,Alimentos!$A:$L,2,FALSE) -> ml | E11: =C11/VLOOKUP(B11,Alimentos!$A:$L,3,FALSE)*VLOOKUP(B11,Alimentos!$A:$L,4,FALSE) -> 122 | F11: =C11/VLOOKUP(B11,Alimentos!$A:$L,3,FALSE)*VLOOKUP(B11,Alimentos!$A:$L,5,FALSE) -> 6.4 | G11: =C11/VLOOKUP(B11,Alimentos!$A:$L,3,FALSE)*VLOOKUP(B11,Alimentos!$A:$L,6,FALSE) -> 9.4 | H11: =C11/VLOOKUP(B11,Alimentos!$A:$L,3,FALSE)*VLOOKUP(B11,Alimentos!$A:$L,7,FALSE) -> 6.6 | I11: =C11/VLOOKUP(B11,Alimentos!$A:$L,3,FALSE)*VLOOKUP(B11,Alimentos!$A:$L,8,FALSE) -> 0
A12: Almoço | B12: Arroz branco cozido | C12: 200 | D12: =VLOOKUP(B12,Alimentos!$A:$L,2,FALSE) -> g | E12: =C12/VLOOKUP(B12,Alimentos!$A:$L,3,FALSE)*VLOOKUP(B12,Alimentos!$A:$L,4,FALSE) -> 256 | F12: =C12/VLOOKUP(B12,Alimentos!$A:$L,3,FALSE)*VLOOKUP(B12,Alimentos!$A:$L,5,FALSE) -> 5 | G12: =C12/VLOOKUP(B12,Alimentos!$A:$L,3,FALSE)*VLOOKUP(B12,Alimentos!$A:$L,6,FALSE) -> 56.2 | H12: =C12/VLOOKUP(B12,Alimentos!$A:$L,3,FALSE)*VLOOKUP(B12,Alimentos!$A:$L,7,FALSE) -> 0.4 | I12: =C12/VLOOKUP(B12,Alimentos!$A:$L,3,FALSE)*VLOOKUP(B12,Alimentos!$A:$L,8,FALSE) -> 3.2 | J12: Porção ajustada para aproximar o total de 2.400 kcal
A13: Almoço | B13: Feijão carioca cozido | C13: 100 | D13: =VLOOKUP(B13,Alimentos!$A:$L,2,FALSE) -> g | E13: =C13/VLOOKUP(B13,Alimentos!$A:$L,3,FALSE)*VLOOKUP(B13,Alimentos!$A:$L,4,FALSE) -> 76 | F13: =C13/VLOOKUP(B13,Alimentos!$A:$L,3,FALSE)*VLOOKUP(B13,Alimentos!$A:$L,5,FALSE) -> 4.8 | G13: =C13/VLOOKUP(B13,Alimentos!$A:$L,3,FALSE)*VLOOKUP(B13,Alimentos!$A:$L,6,FALSE) -> 13.6 | H13: =C13/VLOOKUP(B13,Alimentos!$A:$L,3,FALSE)*VLOOKUP(B13,Alimentos!$A:$L,7,FALSE) -> 0.5 | I13: =C13/VLOOKUP(B13,Alimentos!$A:$L,3,FALSE)*VLOOKUP(B13,Alimentos!$A:$L,8,FALSE) -> 8.5
A14: Almoço | B14: Peito de frango cozido | C14: 100 | D14: =VLOOKUP(B14,Alimentos!$A:$L,2,FALSE) -> g | E14: =C14/VLOOKUP(B14,Alimentos!$A:$L,3,FALSE)*VLOOKUP(B14,Alimentos!$A:$L,4,FALSE) -> 163 | F14: =C14/VLOOKUP(B14,Alimentos!$A:$L,3,FALSE)*VLOOKUP(B14,Alimentos!$A:$L,5,FALSE) -> 31.5 | G14: =C14/VLOOKUP(B14,Alimentos!$A:$L,3,FALSE)*VLOOKUP(B14,Alimentos!$A:$L,6,FALSE) -> 0 | H14: =C14/VLOOKUP(B14,Alimentos!$A:$L,3,FALSE)*VLOOKUP(B14,Alimentos!$A:$L,7,FALSE) -> 3.2 | I14: =C14/VLOOKUP(B14,Alimentos!$A:$L,3,FALSE)*VLOOKUP(B14,Alimentos!$A:$L,8,FALSE) -> 0 | J14: Ajustado de 130–150 g para evitar excesso na soma do dia
A15: Almoço | B15: Cenoura cozida | C15: 100 | D15: =VLOOKUP(B15,Alimentos!$A:$L,2,FALSE) -> g | E15: =C15/VLOOKUP(B15,Alimentos!$A:$L,3,FALSE)*VLOOKUP(B15,Alimentos!$A:$L,4,FALSE) -> 30 | F15: =C15/VLOOKUP(B15,Alimentos!$A:$L,3,FALSE)*VLOOKUP(B15,Alimentos!$A:$L,5,FALSE) -> 0.8 | G15: =C15/VLOOKUP(B15,Alimentos!$A:$L,3,FALSE)*VLOOKUP(B15,Alimentos!$A:$L,6,FALSE) -> 6.7 | H15: =C15/VLOOKUP(B15,Alimentos!$A:$L,3,FALSE)*VLOOKUP(B15,Alimentos!$A:$L,7,FALSE) -> 0.2 | I15: =C15/VLOOKUP(B15,Alimentos!$A:$L,3,FALSE)*VLOOKUP(B15,Alimentos!$A:$L,8,FALSE) -> 2.6 | J15: Exemplo de legumes
A16: Almoço | B16: Alface crua | C16: 50 | D16: =VLOOKUP(B16,Alimentos!$A:$L,2,FALSE) -> g | E16: =C16/VLOOKUP(B16,Alimentos!$A:$L,3,FALSE)*VLOOKUP(B16,Alimentos!$A:$L,4,FALSE) -> 5.5 | F16: =C16/VLOOKUP(B16,Alimentos!$A:$L,3,FALSE)*VLOOKUP(B16,Alimentos!$A:$L,5,FALSE) -> 0.65 | G16: =C16/VLOOKUP(B16,Alimentos!$A:$L,3,FALSE)*VLOOKUP(B16,Alimentos!$A:$L,6,FALSE) -> 0.85 | H16: =C16/VLOOKUP(B16,Alimentos!$A:$L,3,FALSE)*VLOOKUP(B16,Alimentos!$A:$L,7,FALSE) -> 0.1 | I16: =C16/VLOOKUP(B16,Alimentos!$A:$L,3,FALSE)*VLOOKUP(B16,Alimentos!$A:$L,8,FALSE) -> 0.9
A17: Almoço | B17: Azeite | C17: 10 | D17: =VLOOKUP(B17,Alimentos!$A:$L,2,FALSE) -> g | E17: =C17/VLOOKUP(B17,Alimentos!$A:$L,3,FALSE)*VLOOKUP(B17,Alimentos!$A:$L,4,FALSE) -> 88.4 | F17: =C17/VLOOKUP(B17,Alimentos!$A:$L,3,FALSE)*VLOOKUP(B17,Alimentos!$A:$L,5,FALSE) -> 0 | G17: =C17/VLOOKUP(B17,Alimentos!$A:$L,3,FALSE)*VLOOKUP(B17,Alimentos!$A:$L,6,FALSE) -> 0 | H17: =C17/VLOOKUP(B17,Alimentos!$A:$L,3,FALSE)*VLOOKUP(B17,Alimentos!$A:$L,7,FALSE) -> 10 | I17: =C17/VLOOKUP(B17,Alimentos!$A:$L,3,FALSE)*VLOOKUP(B17,Alimentos!$A:$L,8,FALSE) -> 0 | J17: Gordura estimada do preparo; não duplicar
A18: Almoço | B18: Laranja pera | C18: 150 | D18: =VLOOKUP(B18,Alimentos!$A:$L,2,FALSE) -> g | E18: =C18/VLOOKUP(B18,Alimentos!$A:$L,3,FALSE)*VLOOKUP(B18,Alimentos!$A:$L,4,FALSE) -> 55.5 | F18: =C18/VLOOKUP(B18,Alimentos!$A:$L,3,FALSE)*VLOOKUP(B18,Alimentos!$A:$L,5,FALSE) -> 1.5 | G18: =C18/VLOOKUP(B18,Alimentos!$A:$L,3,FALSE)*VLOOKUP(B18,Alimentos!$A:$L,6,FALSE) -> 13.35 | H18: =C18/VLOOKUP(B18,Alimentos!$A:$L,3,FALSE)*VLOOKUP(B18,Alimentos!$A:$L,7,FALSE) -> 0.15 | I18: =C18/VLOOKUP(B18,Alimentos!$A:$L,3,FALSE)*VLOOKUP(B18,Alimentos!$A:$L,8,FALSE) -> 1.2
A19: Jantar | B19: Arroz branco cozido | C19: 200 | D19: =VLOOKUP(B19,Alimentos!$A:$L,2,FALSE) -> g | E19: =C19/VLOOKUP(B19,Alimentos!$A:$L,3,FALSE)*VLOOKUP(B19,Alimentos!$A:$L,4,FALSE) -> 256 | F19: =C19/VLOOKUP(B19,Alimentos!$A:$L,3,FALSE)*VLOOKUP(B19,Alimentos!$A:$L,5,FALSE) -> 5 | G19: =C19/VLOOKUP(B19,Alimentos!$A:$L,3,FALSE)*VLOOKUP(B19,Alimentos!$A:$L,6,FALSE) -> 56.2 | H19: =C19/VLOOKUP(B19,Alimentos!$A:$L,3,FALSE)*VLOOKUP(B19,Alimentos!$A:$L,7,FALSE) -> 0.4 | I19: =C19/VLOOKUP(B19,Alimentos!$A:$L,3,FALSE)*VLOOKUP(B19,Alimentos!$A:$L,8,FALSE) -> 3.2 | J19: Porção ajustada para aproximar o total de 2.400 kcal
A20: Jantar | B20: Feijão carioca cozido | C20: 100 | D20: =VLOOKUP(B20,Alimentos!$A:$L,2,FALSE) -> g | E20: =C20/VLOOKUP(B20,Alimentos!$A:$L,3,FALSE)*VLOOKUP(B20,Alimentos!$A:$L,4,FALSE) -> 76 | F20: =C20/VLOOKUP(B20,Alimentos!$A:$L,3,FALSE)*VLOOKUP(B20,Alimentos!$A:$L,5,FALSE) -> 4.8 | G20: =C20/VLOOKUP(B20,Alimentos!$A:$L,3,FALSE)*VLOOKUP(B20,Alimentos!$A:$L,6,FALSE) -> 13.6 | H20: =C20/VLOOKUP(B20,Alimentos!$A:$L,3,FALSE)*VLOOKUP(B20,Alimentos!$A:$L,7,FALSE) -> 0.5 | I20: =C20/VLOOKUP(B20,Alimentos!$A:$L,3,FALSE)*VLOOKUP(B20,Alimentos!$A:$L,8,FALSE) -> 8.5
A21: Jantar | B21: Peito de frango cozido | C21: 100 | D21: =VLOOKUP(B21,Alimentos!$A:$L,2,FALSE) -> g | E21: =C21/VLOOKUP(B21,Alimentos!$A:$L,3,FALSE)*VLOOKUP(B21,Alimentos!$A:$L,4,FALSE) -> 163 | F21: =C21/VLOOKUP(B21,Alimentos!$A:$L,3,FALSE)*VLOOKUP(B21,Alimentos!$A:$L,5,FALSE) -> 31.5 | G21: =C21/VLOOKUP(B21,Alimentos!$A:$L,3,FALSE)*VLOOKUP(B21,Alimentos!$A:$L,6,FALSE) -> 0 | H21: =C21/VLOOKUP(B21,Alimentos!$A:$L,3,FALSE)*VLOOKUP(B21,Alimentos!$A:$L,7,FALSE) -> 3.2 | I21: =C21/VLOOKUP(B21,Alimentos!$A:$L,3,FALSE)*VLOOKUP(B21,Alimentos!$A:$L,8,FALSE) -> 0 | J21: Ajustado de 130–150 g para evitar excesso na soma do dia
A22: Jantar | B22: Cenoura cozida | C22: 100 | D22: =VLOOKUP(B22,Alimentos!$A:$L,2,FALSE) -> g | E22: =C22/VLOOKUP(B22,Alimentos!$A:$L,3,FALSE)*VLOOKUP(B22,Alimentos!$A:$L,4,FALSE) -> 30 | F22: =C22/VLOOKUP(B22,Alimentos!$A:$L,3,FALSE)*VLOOKUP(B22,Alimentos!$A:$L,5,FALSE) -> 0.8 | G22: =C22/VLOOKUP(B22,Alimentos!$A:$L,3,FALSE)*VLOOKUP(B22,Alimentos!$A:$L,6,FALSE) -> 6.7 | H22: =C22/VLOOKUP(B22,Alimentos!$A:$L,3,FALSE)*VLOOKUP(B22,Alimentos!$A:$L,7,FALSE) -> 0.2 | I22: =C22/VLOOKUP(B22,Alimentos!$A:$L,3,FALSE)*VLOOKUP(B22,Alimentos!$A:$L,8,FALSE) -> 2.6 | J22: Exemplo de legumes
A23: Jantar | B23: Alface crua | C23: 50 | D23: =VLOOKUP(B23,Alimentos!$A:$L,2,FALSE) -> g | E23: =C23/VLOOKUP(B23,Alimentos!$A:$L,3,FALSE)*VLOOKUP(B23,Alimentos!$A:$L,4,FALSE) -> 5.5 | F23: =C23/VLOOKUP(B23,Alimentos!$A:$L,3,FALSE)*VLOOKUP(B23,Alimentos!$A:$L,5,FALSE) -> 0.65 | G23: =C23/VLOOKUP(B23,Alimentos!$A:$L,3,FALSE)*VLOOKUP(B23,Alimentos!$A:$L,6,FALSE) -> 0.85 | H23: =C23/VLOOKUP(B23,Alimentos!$A:$L,3,FALSE)*VLOOKUP(B23,Alimentos!$A:$L,7,FALSE) -> 0.1 | I23: =C23/VLOOKUP(B23,Alimentos!$A:$L,3,FALSE)*VLOOKUP(B23,Alimentos!$A:$L,8,FALSE) -> 0.9
A24: Jantar | B24: Azeite | C24: 10 | D24: =VLOOKUP(B24,Alimentos!$A:$L,2,FALSE) -> g | E24: =C24/VLOOKUP(B24,Alimentos!$A:$L,3,FALSE)*VLOOKUP(B24,Alimentos!$A:$L,4,FALSE) -> 88.4 | F24: =C24/VLOOKUP(B24,Alimentos!$A:$L,3,FALSE)*VLOOKUP(B24,Alimentos!$A:$L,5,FALSE) -> 0 | G24: =C24/VLOOKUP(B24,Alimentos!$A:$L,3,FALSE)*VLOOKUP(B24,Alimentos!$A:$L,6,FALSE) -> 0 | H24: =C24/VLOOKUP(B24,Alimentos!$A:$L,3,FALSE)*VLOOKUP(B24,Alimentos!$A:$L,7,FALSE) -> 10 | I24: =C24/VLOOKUP(B24,Alimentos!$A:$L,3,FALSE)*VLOOKUP(B24,Alimentos!$A:$L,8,FALSE) -> 0 | J24: Gordura estimada do preparo; não duplicar
A25: Lanche | B25: Whey (rótulo a conferir) | C25: 10 | D25: =VLOOKUP(B25,Alimentos!$A:$L,2,FALSE) -> g | E25: =C25/VLOOKUP(B25,Alimentos!$A:$L,3,FALSE)*VLOOKUP(B25,Alimentos!$A:$L,4,FALSE) -> 40 | F25: =C25/VLOOKUP(B25,Alimentos!$A:$L,3,FALSE)*VLOOKUP(B25,Alimentos!$A:$L,5,FALSE) -> 7.6666667 | G25: =C25/VLOOKUP(B25,Alimentos!$A:$L,3,FALSE)*VLOOKUP(B25,Alimentos!$A:$L,6,FALSE) -> 1.3333333 | H25: =C25/VLOOKUP(B25,Alimentos!$A:$L,3,FALSE)*VLOOKUP(B25,Alimentos!$A:$L,7,FALSE) -> 0.43333333 | I25: =C25/VLOOKUP(B25,Alimentos!$A:$L,3,FALSE)*VLOOKUP(B25,Alimentos!$A:$L,8,FALSE) -> 0 | J25: 10 g de pó na proposta atual; conferir rótulo.
A26: Lanche | B26: Leite integral (estimativa) | C26: 200 | D26: =VLOOKUP(B26,Alimentos!$A:$L,2,FALSE) -> ml | E26: =C26/VLOOKUP(B26,Alimentos!$A:$L,3,FALSE)*VLOOKUP(B26,Alimentos!$A:$L,4,FALSE) -> 122 | F26: =C26/VLOOKUP(B26,Alimentos!$A:$L,3,FALSE)*VLOOKUP(B26,Alimentos!$A:$L,5,FALSE) -> 6.4 | G26: =C26/VLOOKUP(B26,Alimentos!$A:$L,3,FALSE)*VLOOKUP(B26,Alimentos!$A:$L,6,FALSE) -> 9.4 | H26: =C26/VLOOKUP(B26,Alimentos!$A:$L,3,FALSE)*VLOOKUP(B26,Alimentos!$A:$L,7,FALSE) -> 6.6 | I26: =C26/VLOOKUP(B26,Alimentos!$A:$L,3,FALSE)*VLOOKUP(B26,Alimentos!$A:$L,8,FALSE) -> 0
A27: Lanche | B27: Banana nanica | C27: 100 | D27: =VLOOKUP(B27,Alimentos!$A:$L,2,FALSE) -> g | E27: =C27/VLOOKUP(B27,Alimentos!$A:$L,3,FALSE)*VLOOKUP(B27,Alimentos!$A:$L,4,FALSE) -> 92 | F27: =C27/VLOOKUP(B27,Alimentos!$A:$L,3,FALSE)*VLOOKUP(B27,Alimentos!$A:$L,5,FALSE) -> 1.4 | G27: =C27/VLOOKUP(B27,Alimentos!$A:$L,3,FALSE)*VLOOKUP(B27,Alimentos!$A:$L,6,FALSE) -> 23.8 | H27: =C27/VLOOKUP(B27,Alimentos!$A:$L,3,FALSE)*VLOOKUP(B27,Alimentos!$A:$L,7,FALSE) -> 0.1 | I27: =C27/VLOOKUP(B27,Alimentos!$A:$L,3,FALSE)*VLOOKUP(B27,Alimentos!$A:$L,8,FALSE) -> 1.9
A28: Lanche | B28: Aveia em flocos | C28: 40 | D28: =VLOOKUP(B28,Alimentos!$A:$L,2,FALSE) -> g | E28: =C28/VLOOKUP(B28,Alimentos!$A:$L,3,FALSE)*VLOOKUP(B28,Alimentos!$A:$L,4,FALSE) -> 157.6 | F28: =C28/VLOOKUP(B28,Alimentos!$A:$L,3,FALSE)*VLOOKUP(B28,Alimentos!$A:$L,5,FALSE) -> 5.56 | G28: =C28/VLOOKUP(B28,Alimentos!$A:$L,3,FALSE)*VLOOKUP(B28,Alimentos!$A:$L,6,FALSE) -> 26.64 | H28: =C28/VLOOKUP(B28,Alimentos!$A:$L,3,FALSE)*VLOOKUP(B28,Alimentos!$A:$L,7,FALSE) -> 3.4 | I28: =C28/VLOOKUP(B28,Alimentos!$A:$L,3,FALSE)*VLOOKUP(B28,Alimentos!$A:$L,8,FALSE) -> 3.64
A29: Ceia | B29: Banana nanica | C29: 100 | D29: =VLOOKUP(B29,Alimentos!$A:$L,2,FALSE) -> g | E29: =C29/VLOOKUP(B29,Alimentos!$A:$L,3,FALSE)*VLOOKUP(B29,Alimentos!$A:$L,4,FALSE) -> 92 | F29: =C29/VLOOKUP(B29,Alimentos!$A:$L,3,FALSE)*VLOOKUP(B29,Alimentos!$A:$L,5,FALSE) -> 1.4 | G29: =C29/VLOOKUP(B29,Alimentos!$A:$L,3,FALSE)*VLOOKUP(B29,Alimentos!$A:$L,6,FALSE) -> 23.8 | H29: =C29/VLOOKUP(B29,Alimentos!$A:$L,3,FALSE)*VLOOKUP(B29,Alimentos!$A:$L,7,FALSE) -> 0.1 | I29: =C29/VLOOKUP(B29,Alimentos!$A:$L,3,FALSE)*VLOOKUP(B29,Alimentos!$A:$L,8,FALSE) -> 1.9 | J29: Pode deslocar para antes do Muay Thai
A31: Total da proposta | E31: =SUM(E6:E29) -> 2440.7 | F31: =SUM(F6:F29) -> 144.90667 | G31: =SUM(G6:G29) -> 314.21333 | H31: =SUM(H6:H29) -> 69.523333 | I31: =SUM(I6:I29) -> 44.39

Sheet Equivalências
A2: Trocas por nutriente principal
A3: Trocas igualam um nutriente, não todos os macros. Quantidades calculadas são aproximações; confira o total da dieta.
A5: Base | B5: Qtd. base | C5: Critério | D5: Alternativa | E5: Qtd. equivalente | F5: Unidade | G5: kcal base | H5: kcal alternativa | I5: Diferença kcal | J5: Proteína alt. | K5: Carboidrato alt. | L5: Gordura alt. | M5: Observação
A6: Peito de frango cozido | B6: 100 | C6: Proteína | D6: Ovo inteiro cozido | E6: =B6/VLOOKUP(A6,Alimentos!$A:$L,3,FALSE)*VLOOKUP(A6,Alimentos!$A:$L,IF(C6="Proteína",5,IF(C6="Carboidrato",6,7)),FALSE)/VLOOKUP(D6,Alimentos!$A:$L,IF(C6="Proteína",5,IF(C6="Carboidrato",6,7)),FALSE)*VLOOKUP(D6,Alimentos!$A:$L,3,FALSE) -> 236.84211 | F6: =VLOOKUP(D6,Alimentos!$A:$L,2,FALSE) -> g | G6: =B6/VLOOKUP(A6,Alimentos!$A:$L,3,FALSE)*VLOOKUP(A6,Alimentos!$A:$L,4,FALSE) -> 163 | H6: =E6/VLOOKUP(D6,Alimentos!$A:$L,3,FALSE)*VLOOKUP(D6,Alimentos!$A:$L,4,FALSE) -> 345.78947 | I6: =H6-G6 -> 182.78947 | J6: =E6/VLOOKUP(D6,Alimentos!$A:$L,3,FALSE)*VLOOKUP(D6,Alimentos!$A:$L,5,FALSE) -> 31.5 | K6: =E6/VLOOKUP(D6,Alimentos!$A:$L,3,FALSE)*VLOOKUP(D6,Alimentos!$A:$L,6,FALSE) -> 1.4210526 | L6: =E6/VLOOKUP(D6,Alimentos!$A:$L,3,FALSE)*VLOOKUP(D6,Alimentos!$A:$L,7,FALSE) -> 22.5 | M6: Ovos: dividir gramas por 50 para estimar unidades. A gordura e as calorias aumentam nesta troca.
A7: Ovo inteiro cozido | B7: 150 | C7: Proteína | D7: Peito de frango cozido | E7: =B7/VLOOKUP(A7,Alimentos!$A:$L,3,FALSE)*VLOOKUP(A7,Alimentos!$A:$L,IF(C7="Proteína",5,IF(C7="Carboidrato",6,7)),FALSE)/VLOOKUP(D7,Alimentos!$A:$L,IF(C7="Proteína",5,IF(C7="Carboidrato",6,7)),FALSE)*VLOOKUP(D7,Alimentos!$A:$L,3,FALSE) -> 63.333333 | F7: =VLOOKUP(D7,Alimentos!$A:$L,2,FALSE) -> g | G7: =B7/VLOOKUP(A7,Alimentos!$A:$L,3,FALSE)*VLOOKUP(A7,Alimentos!$A:$L,4,FALSE) -> 219 | H7: =E7/VLOOKUP(D7,Alimentos!$A:$L,3,FALSE)*VLOOKUP(D7,Alimentos!$A:$L,4,FALSE) -> 103.23333 | I7: =H7-G7 -> -115.76667 | J7: =E7/VLOOKUP(D7,Alimentos!$A:$L,3,FALSE)*VLOOKUP(D7,Alimentos!$A:$L,5,FALSE) -> 19.95 | K7: =E7/VLOOKUP(D7,Alimentos!$A:$L,3,FALSE)*VLOOKUP(D7,Alimentos!$A:$L,6,FALSE) -> 0 | L7: =E7/VLOOKUP(D7,Alimentos!$A:$L,3,FALSE)*VLOOKUP(D7,Alimentos!$A:$L,7,FALSE) -> 2.0266667
A8: Whey (rótulo a conferir) | B8: 30 | C8: Proteína | D8: Peito de frango cozido | E8: =B8/VLOOKUP(A8,Alimentos!$A:$L,3,FALSE)*VLOOKUP(A8,Alimentos!$A:$L,IF(C8="Proteína",5,IF(C8="Carboidrato",6,7)),FALSE)/VLOOKUP(D8,Alimentos!$A:$L,IF(C8="Proteína",5,IF(C8="Carboidrato",6,7)),FALSE)*VLOOKUP(D8,Alimentos!$A:$L,3,FALSE) -> 73.015873 | F8: =VLOOKUP(D8,Alimentos!$A:$L,2,FALSE) -> g | G8: =B8/VLOOKUP(A8,Alimentos!$A:$L,3,FALSE)*VLOOKUP(A8,Alimentos!$A:$L,4,FALSE) -> 120 | H8: =E8/VLOOKUP(D8,Alimentos!$A:$L,3,FALSE)*VLOOKUP(D8,Alimentos!$A:$L,4,FALSE) -> 119.01587 | I8: =H8-G8 -> -0.98412698 | J8: =E8/VLOOKUP(D8,Alimentos!$A:$L,3,FALSE)*VLOOKUP(D8,Alimentos!$A:$L,5,FALSE) -> 23 | K8: =E8/VLOOKUP(D8,Alimentos!$A:$L,3,FALSE)*VLOOKUP(D8,Alimentos!$A:$L,6,FALSE) -> 0 | L8: =E8/VLOOKUP(D8,Alimentos!$A:$L,3,FALSE)*VLOOKUP(D8,Alimentos!$A:$L,7,FALSE) -> 2.3365079
A9: Whey (rótulo a conferir) | B9: 30 | C9: Proteína | D9: Ovo inteiro cozido | E9: =B9/VLOOKUP(A9,Alimentos!$A:$L,3,FALSE)*VLOOKUP(A9,Alimentos!$A:$L,IF(C9="Proteína",5,IF(C9="Carboidrato",6,7)),FALSE)/VLOOKUP(D9,Alimentos!$A:$L,IF(C9="Proteína",5,IF(C9="Carboidrato",6,7)),FALSE)*VLOOKUP(D9,Alimentos!$A:$L,3,FALSE) -> 172.93233 | F9: =VLOOKUP(D9,Alimentos!$A:$L,2,FALSE) -> g | G9: =B9/VLOOKUP(A9,Alimentos!$A:$L,3,FALSE)*VLOOKUP(A9,Alimentos!$A:$L,4,FALSE) -> 120 | H9: =E9/VLOOKUP(D9,Alimentos!$A:$L,3,FALSE)*VLOOKUP(D9,Alimentos!$A:$L,4,FALSE) -> 252.4812 | I9: =H9-G9 -> 132.4812 | J9: =E9/VLOOKUP(D9,Alimentos!$A:$L,3,FALSE)*VLOOKUP(D9,Alimentos!$A:$L,5,FALSE) -> 23 | K9: =E9/VLOOKUP(D9,Alimentos!$A:$L,3,FALSE)*VLOOKUP(D9,Alimentos!$A:$L,6,FALSE) -> 1.037594 | L9: =E9/VLOOKUP(D9,Alimentos!$A:$L,3,FALSE)*VLOOKUP(D9,Alimentos!$A:$L,7,FALSE) -> 16.428571
A10: Peito de frango cozido | B10: 100 | C10: Proteína | D10: Merluza assada | E10: =B10/VLOOKUP(A10,Alimentos!$A:$L,3,FALSE)*VLOOKUP(A10,Alimentos!$A:$L,IF(C10="Proteína",5,IF(C10="Carboidrato",6,7)),FALSE)/VLOOKUP(D10,Alimentos!$A:$L,IF(C10="Proteína",5,IF(C10="Carboidrato",6,7)),FALSE)*VLOOKUP(D10,Alimentos!$A:$L,3,FALSE) -> 118.42105 | F10: =VLOOKUP(D10,Alimentos!$A:$L,2,FALSE) -> g | G10: =B10/VLOOKUP(A10,Alimentos!$A:$L,3,FALSE)*VLOOKUP(A10,Alimentos!$A:$L,4,FALSE) -> 163 | H10: =E10/VLOOKUP(D10,Alimentos!$A:$L,3,FALSE)*VLOOKUP(D10,Alimentos!$A:$L,4,FALSE) -> 144.47368 | I10: =H10-G10 -> -18.526316 | J10: =E10/VLOOKUP(D10,Alimentos!$A:$L,3,FALSE)*VLOOKUP(D10,Alimentos!$A:$L,5,FALSE) -> 31.5 | K10: =E10/VLOOKUP(D10,Alimentos!$A:$L,3,FALSE)*VLOOKUP(D10,Alimentos!$A:$L,6,FALSE) -> 0 | L10: =E10/VLOOKUP(D10,Alimentos!$A:$L,3,FALSE)*VLOOKUP(D10,Alimentos!$A:$L,7,FALSE) -> 1.0657895
A11: Ovo inteiro cozido | B11: 150 | C11: Proteína | D11: Clara de ovo cozida | E11: =B11/VLOOKUP(A11,Alimentos!$A:$L,3,FALSE)*VLOOKUP(A11,Alimentos!$A:$L,IF(C11="Proteína",5,IF(C11="Carboidrato",6,7)),FALSE)/VLOOKUP(D11,Alimentos!$A:$L,IF(C11="Proteína",5,IF(C11="Carboidrato",6,7)),FALSE)*VLOOKUP(D11,Alimentos!$A:$L,3,FALSE) -> 148.8806 | F11: =VLOOKUP(D11,Alimentos!$A:$L,2,FALSE) -> g | G11: =B11/VLOOKUP(A11,Alimentos!$A:$L,3,FALSE)*VLOOKUP(A11,Alimentos!$A:$L,4,FALSE) -> 219 | H11: =E11/VLOOKUP(D11,Alimentos!$A:$L,3,FALSE)*VLOOKUP(D11,Alimentos!$A:$L,4,FALSE) -> 87.839552 | I11: =H11-G11 -> -131.16045 | J11: =E11/VLOOKUP(D11,Alimentos!$A:$L,3,FALSE)*VLOOKUP(D11,Alimentos!$A:$L,5,FALSE) -> 19.95 | K11: =E11/VLOOKUP(D11,Alimentos!$A:$L,3,FALSE)*VLOOKUP(D11,Alimentos!$A:$L,6,FALSE) -> 0 | L11: =E11/VLOOKUP(D11,Alimentos!$A:$L,3,FALSE)*VLOOKUP(D11,Alimentos!$A:$L,7,FALSE) -> 0.1488806
A12: Arroz branco cozido | B12: 150 | C12: Carboidrato | D12: Batata inglesa cozida | E12: =B12/VLOOKUP(A12,Alimentos!$A:$L,3,FALSE)*VLOOKUP(A12,Alimentos!$A:$L,IF(C12="Proteína",5,IF(C12="Carboidrato",6,7)),FALSE)/VLOOKUP(D12,Alimentos!$A:$L,IF(C12="Proteína",5,IF(C12="Carboidrato",6,7)),FALSE)*VLOOKUP(D12,Alimentos!$A:$L,3,FALSE) -> 354.20168 | F12: =VLOOKUP(D12,Alimentos!$A:$L,2,FALSE) -> g | G12: =B12/VLOOKUP(A12,Alimentos!$A:$L,3,FALSE)*VLOOKUP(A12,Alimentos!$A:$L,4,FALSE) -> 192 | H12: =E12/VLOOKUP(D12,Alimentos!$A:$L,3,FALSE)*VLOOKUP(D12,Alimentos!$A:$L,4,FALSE) -> 184.18487 | I12: =H12-G12 -> -7.815126 | J12: =E12/VLOOKUP(D12,Alimentos!$A:$L,3,FALSE)*VLOOKUP(D12,Alimentos!$A:$L,5,FALSE) -> 4.2504202 | K12: =E12/VLOOKUP(D12,Alimentos!$A:$L,3,FALSE)*VLOOKUP(D12,Alimentos!$A:$L,6,FALSE) -> 42.15 | L12: =E12/VLOOKUP(D12,Alimentos!$A:$L,3,FALSE)*VLOOKUP(D12,Alimentos!$A:$L,7,FALSE) -> 0
A13: Arroz branco cozido | B13: 150 | C13: Carboidrato | D13: Batata doce cozida | E13: =B13/VLOOKUP(A13,Alimentos!$A:$L,3,FALSE)*VLOOKUP(A13,Alimentos!$A:$L,IF(C13="Proteína",5,IF(C13="Carboidrato",6,7)),FALSE)/VLOOKUP(D13,Alimentos!$A:$L,IF(C13="Proteína",5,IF(C13="Carboidrato",6,7)),FALSE)*VLOOKUP(D13,Alimentos!$A:$L,3,FALSE) -> 229.07609 | F13: =VLOOKUP(D13,Alimentos!$A:$L,2,FALSE) -> g | G13: =B13/VLOOKUP(A13,Alimentos!$A:$L,3,FALSE)*VLOOKUP(A13,Alimentos!$A:$L,4,FALSE) -> 192 | H13: =E13/VLOOKUP(D13,Alimentos!$A:$L,3,FALSE)*VLOOKUP(D13,Alimentos!$A:$L,4,FALSE) -> 176.38859 | I13: =H13-G13 -> -15.611413 | J13: =E13/VLOOKUP(D13,Alimentos!$A:$L,3,FALSE)*VLOOKUP(D13,Alimentos!$A:$L,5,FALSE) -> 1.3744565 | K13: =E13/VLOOKUP(D13,Alimentos!$A:$L,3,FALSE)*VLOOKUP(D13,Alimentos!$A:$L,6,FALSE) -> 42.15 | L13: =E13/VLOOKUP(D13,Alimentos!$A:$L,3,FALSE)*VLOOKUP(D13,Alimentos!$A:$L,7,FALSE) -> 0.22907609
A14: Pão integral | B14: 50 | C14: Carboidrato | D14: Aveia em flocos | E14: =B14/VLOOKUP(A14,Alimentos!$A:$L,3,FALSE)*VLOOKUP(A14,Alimentos!$A:$L,IF(C14="Proteína",5,IF(C14="Carboidrato",6,7)),FALSE)/VLOOKUP(D14,Alimentos!$A:$L,IF(C14="Proteína",5,IF(C14="Carboidrato",6,7)),FALSE)*VLOOKUP(D14,Alimentos!$A:$L,3,FALSE) -> 37.462462 | F14: =VLOOKUP(D14,Alimentos!$A:$L,2,FALSE) -> g | G14: =B14/VLOOKUP(A14,Alimentos!$A:$L,3,FALSE)*VLOOKUP(A14,Alimentos!$A:$L,4,FALSE) -> 126.5 | H14: =E14/VLOOKUP(D14,Alimentos!$A:$L,3,FALSE)*VLOOKUP(D14,Alimentos!$A:$L,4,FALSE) -> 147.6021 | I14: =H14-G14 -> 21.102102 | J14: =E14/VLOOKUP(D14,Alimentos!$A:$L,3,FALSE)*VLOOKUP(D14,Alimentos!$A:$L,5,FALSE) -> 5.2072823 | K14: =E14/VLOOKUP(D14,Alimentos!$A:$L,3,FALSE)*VLOOKUP(D14,Alimentos!$A:$L,6,FALSE) -> 24.95 | L14: =E14/VLOOKUP(D14,Alimentos!$A:$L,3,FALSE)*VLOOKUP(D14,Alimentos!$A:$L,7,FALSE) -> 3.1843093
A15: Banana nanica | B15: 100 | C15: Carboidrato | D15: Laranja pera | E15: =B15/VLOOKUP(A15,Alimentos!$A:$L,3,FALSE)*VLOOKUP(A15,Alimentos!$A:$L,IF(C15="Proteína",5,IF(C15="Carboidrato",6,7)),FALSE)/VLOOKUP(D15,Alimentos!$A:$L,IF(C15="Proteína",5,IF(C15="Carboidrato",6,7)),FALSE)*VLOOKUP(D15,Alimentos!$A:$L,3,FALSE) -> 267.41573 | F15: =VLOOKUP(D15,Alimentos!$A:$L,2,FALSE) -> g | G15: =B15/VLOOKUP(A15,Alimentos!$A:$L,3,FALSE)*VLOOKUP(A15,Alimentos!$A:$L,4,FALSE) -> 92 | H15: =E15/VLOOKUP(D15,Alimentos!$A:$L,3,FALSE)*VLOOKUP(D15,Alimentos!$A:$L,4,FALSE) -> 98.94382 | I15: =H15-G15 -> 6.9438202 | J15: =E15/VLOOKUP(D15,Alimentos!$A:$L,3,FALSE)*VLOOKUP(D15,Alimentos!$A:$L,5,FALSE) -> 2.6741573 | K15: =E15/VLOOKUP(D15,Alimentos!$A:$L,3,FALSE)*VLOOKUP(D15,Alimentos!$A:$L,6,FALSE) -> 23.8 | L15: =E15/VLOOKUP(D15,Alimentos!$A:$L,3,FALSE)*VLOOKUP(D15,Alimentos!$A:$L,7,FALSE) -> 0.26741573
A16: Feijão carioca cozido | B16: 100 | C16: Carboidrato | D16: Feijão preto cozido | E16: =B16/VLOOKUP(A16,Alimentos!$A:$L,3,FALSE)*VLOOKUP(A16,Alimentos!$A:$L,IF(C16="Proteína",5,IF(C16="Carboidrato",6,7)),FALSE)/VLOOKUP(D16,Alimentos!$A:$L,IF(C16="Proteína",5,IF(C16="Carboidrato",6,7)),FALSE)*VLOOKUP(D16,Alimentos!$A:$L,3,FALSE) -> 97.142857 | F16: =VLOOKUP(D16,Alimentos!$A:$L,2,FALSE) -> g | G16: =B16/VLOOKUP(A16,Alimentos!$A:$L,3,FALSE)*VLOOKUP(A16,Alimentos!$A:$L,4,FALSE) -> 76 | H16: =E16/VLOOKUP(D16,Alimentos!$A:$L,3,FALSE)*VLOOKUP(D16,Alimentos!$A:$L,4,FALSE) -> 74.8 | I16: =H16-G16 -> -1.2 | J16: =E16/VLOOKUP(D16,Alimentos!$A:$L,3,FALSE)*VLOOKUP(D16,Alimentos!$A:$L,5,FALSE) -> 4.3714286 | K16: =E16/VLOOKUP(D16,Alimentos!$A:$L,3,FALSE)*VLOOKUP(D16,Alimentos!$A:$L,6,FALSE) -> 13.6 | L16: =E16/VLOOKUP(D16,Alimentos!$A:$L,3,FALSE)*VLOOKUP(D16,Alimentos!$A:$L,7,FALSE) -> 0.48571429
A17: Feijão carioca cozido | B17: 100 | C17: Carboidrato | D17: Lentilha cozida | E17: =B17/VLOOKUP(A17,Alimentos!$A:$L,3,FALSE)*VLOOKUP(A17,Alimentos!$A:$L,IF(C17="Proteína",5,IF(C17="Carboidrato",6,7)),FALSE)/VLOOKUP(D17,Alimentos!$A:$L,IF(C17="Proteína",5,IF(C17="Carboidrato",6,7)),FALSE)*VLOOKUP(D17,Alimentos!$A:$L,3,FALSE) -> 83.435583 | F17: =VLOOKUP(D17,Alimentos!$A:$L,2,FALSE) -> g | G17: =B17/VLOOKUP(A17,Alimentos!$A:$L,3,FALSE)*VLOOKUP(A17,Alimentos!$A:$L,4,FALSE) -> 76 | H17: =E17/VLOOKUP(D17,Alimentos!$A:$L,3,FALSE)*VLOOKUP(D17,Alimentos!$A:$L,4,FALSE) -> 77.595092 | I17: =H17-G17 -> 1.595092 | J17: =E17/VLOOKUP(D17,Alimentos!$A:$L,3,FALSE)*VLOOKUP(D17,Alimentos!$A:$L,5,FALSE) -> 5.2564417 | K17: =E17/VLOOKUP(D17,Alimentos!$A:$L,3,FALSE)*VLOOKUP(D17,Alimentos!$A:$L,6,FALSE) -> 13.6 | L17: =E17/VLOOKUP(D17,Alimentos!$A:$L,3,FALSE)*VLOOKUP(D17,Alimentos!$A:$L,7,FALSE) -> 0.41717791
A18: Peito de frango cozido | B18: 100 | C18: Proteína | D18: Carne bovina patinho grelhado | E18: =B18/VLOOKUP(A18,Alimentos!$A:$L,3,FALSE)*VLOOKUP(A18,Alimentos!$A:$L,IF(C18="Proteína",5,IF(C18="Carboidrato",6,7)),FALSE)/VLOOKUP(D18,Alimentos!$A:$L,IF(C18="Proteína",5,IF(C18="Carboidrato",6,7)),FALSE)*VLOOKUP(D18,Alimentos!$A:$L,3,FALSE) -> 87.743733 | F18: =VLOOKUP(D18,Alimentos!$A:$L,2,FALSE) -> g | G18: =B18/VLOOKUP(A18,Alimentos!$A:$L,3,FALSE)*VLOOKUP(A18,Alimentos!$A:$L,4,FALSE) -> 163 | H18: =E18/VLOOKUP(D18,Alimentos!$A:$L,3,FALSE)*VLOOKUP(D18,Alimentos!$A:$L,4,FALSE) -> 192.15877 | I18: =H18-G18 -> 29.158774 | J18: =E18/VLOOKUP(D18,Alimentos!$A:$L,3,FALSE)*VLOOKUP(D18,Alimentos!$A:$L,5,FALSE) -> 31.5 | K18: =E18/VLOOKUP(D18,Alimentos!$A:$L,3,FALSE)*VLOOKUP(D18,Alimentos!$A:$L,6,FALSE) -> 0 | L18: =E18/VLOOKUP(D18,Alimentos!$A:$L,3,FALSE)*VLOOKUP(D18,Alimentos!$A:$L,7,FALSE) -> 6.4052925 | M18: Patinho moído ou bife magro; pesar pronto sem óleo.
A19: Peito de frango cozido | B19: 100 | C19: Proteína | D19: Filé de tilápia grelhado | E19: =B19/VLOOKUP(A19,Alimentos!$A:$L,3,FALSE)*VLOOKUP(A19,Alimentos!$A:$L,IF(C19="Proteína",5,IF(C19="Carboidrato",6,7)),FALSE)/VLOOKUP(D19,Alimentos!$A:$L,IF(C19="Proteína",5,IF(C19="Carboidrato",6,7)),FALSE)*VLOOKUP(D19,Alimentos!$A:$L,3,FALSE) -> 121.15385 | F19: =VLOOKUP(D19,Alimentos!$A:$L,2,FALSE) -> g | G19: =B19/VLOOKUP(A19,Alimentos!$A:$L,3,FALSE)*VLOOKUP(A19,Alimentos!$A:$L,4,FALSE) -> 163 | H19: =E19/VLOOKUP(D19,Alimentos!$A:$L,3,FALSE)*VLOOKUP(D19,Alimentos!$A:$L,4,FALSE) -> 155.07692 | I19: =H19-G19 -> -7.9230769 | J19: =E19/VLOOKUP(D19,Alimentos!$A:$L,3,FALSE)*VLOOKUP(D19,Alimentos!$A:$L,5,FALSE) -> 31.5 | K19: =E19/VLOOKUP(D19,Alimentos!$A:$L,3,FALSE)*VLOOKUP(D19,Alimentos!$A:$L,6,FALSE) -> 0 | L19: =E19/VLOOKUP(D19,Alimentos!$A:$L,3,FALSE)*VLOOKUP(D19,Alimentos!$A:$L,7,FALSE) -> 2.4230769 | M19: Pesar pronto sem óleo.
A20: Peito de frango cozido | B20: 100 | C20: Proteína | D20: Atum ralado em conserva em água | E20: =B20/VLOOKUP(A20,Alimentos!$A:$L,3,FALSE)*VLOOKUP(A20,Alimentos!$A:$L,IF(C20="Proteína",5,IF(C20="Carboidrato",6,7)),FALSE)/VLOOKUP(D20,Alimentos!$A:$L,IF(C20="Proteína",5,IF(C20="Carboidrato",6,7)),FALSE)*VLOOKUP(D20,Alimentos!$A:$L,3,FALSE) -> 123.52941 | F20: =VLOOKUP(D20,Alimentos!$A:$L,2,FALSE) -> g | G20: =B20/VLOOKUP(A20,Alimentos!$A:$L,3,FALSE)*VLOOKUP(A20,Alimentos!$A:$L,4,FALSE) -> 163 | H20: =E20/VLOOKUP(D20,Alimentos!$A:$L,3,FALSE)*VLOOKUP(D20,Alimentos!$A:$L,4,FALSE) -> 143.29412 | I20: =H20-G20 -> -19.705882 | J20: =E20/VLOOKUP(D20,Alimentos!$A:$L,3,FALSE)*VLOOKUP(D20,Alimentos!$A:$L,5,FALSE) -> 31.5 | K20: =E20/VLOOKUP(D20,Alimentos!$A:$L,3,FALSE)*VLOOKUP(D20,Alimentos!$A:$L,6,FALSE) -> 0 | L20: =E20/VLOOKUP(D20,Alimentos!$A:$L,3,FALSE)*VLOOKUP(D20,Alimentos!$A:$L,7,FALSE) -> 0.98823529 | M20: Pesar bem escorrido.
A21: Arroz branco cozido | B21: 150 | C21: Carboidrato | D21: Mandioca cozida | E21: =B21/VLOOKUP(A21,Alimentos!$A:$L,3,FALSE)*VLOOKUP(A21,Alimentos!$A:$L,IF(C21="Proteína",5,IF(C21="Carboidrato",6,7)),FALSE)/VLOOKUP(D21,Alimentos!$A:$L,IF(C21="Proteína",5,IF(C21="Carboidrato",6,7)),FALSE)*VLOOKUP(D21,Alimentos!$A:$L,3,FALSE) -> 140.03322 | F21: =VLOOKUP(D21,Alimentos!$A:$L,2,FALSE) -> g | G21: =B21/VLOOKUP(A21,Alimentos!$A:$L,3,FALSE)*VLOOKUP(A21,Alimentos!$A:$L,4,FALSE) -> 192 | H21: =E21/VLOOKUP(D21,Alimentos!$A:$L,3,FALSE)*VLOOKUP(D21,Alimentos!$A:$L,4,FALSE) -> 175.04153 | I21: =H21-G21 -> -16.958472 | J21: =E21/VLOOKUP(D21,Alimentos!$A:$L,3,FALSE)*VLOOKUP(D21,Alimentos!$A:$L,5,FALSE) -> 0.84019934 | K21: =E21/VLOOKUP(D21,Alimentos!$A:$L,3,FALSE)*VLOOKUP(D21,Alimentos!$A:$L,6,FALSE) -> 42.15 | L21: =E21/VLOOKUP(D21,Alimentos!$A:$L,3,FALSE)*VLOOKUP(D21,Alimentos!$A:$L,7,FALSE) -> 0.42009967 | M21: Aipim/macaxeira cozida sem óleo.
A22: Arroz branco cozido | B22: 150 | C22: Carboidrato | D22: Macarrão de sêmola cozido | E22: =B22/VLOOKUP(A22,Alimentos!$A:$L,3,FALSE)*VLOOKUP(A22,Alimentos!$A:$L,IF(C22="Proteína",5,IF(C22="Carboidrato",6,7)),FALSE)/VLOOKUP(D22,Alimentos!$A:$L,IF(C22="Proteína",5,IF(C22="Carboidrato",6,7)),FALSE)*VLOOKUP(D22,Alimentos!$A:$L,3,FALSE) -> 200.71429 | F22: =VLOOKUP(D22,Alimentos!$A:$L,2,FALSE) -> g | G22: =B22/VLOOKUP(A22,Alimentos!$A:$L,3,FALSE)*VLOOKUP(A22,Alimentos!$A:$L,4,FALSE) -> 192 | H22: =E22/VLOOKUP(D22,Alimentos!$A:$L,3,FALSE)*VLOOKUP(D22,Alimentos!$A:$L,4,FALSE) -> 204.72857 | I22: =H22-G22 -> 12.728571 | J22: =E22/VLOOKUP(D22,Alimentos!$A:$L,3,FALSE)*VLOOKUP(D22,Alimentos!$A:$L,5,FALSE) -> 6.8242857 | K22: =E22/VLOOKUP(D22,Alimentos!$A:$L,3,FALSE)*VLOOKUP(D22,Alimentos!$A:$L,6,FALSE) -> 42.15 | L22: =E22/VLOOKUP(D22,Alimentos!$A:$L,3,FALSE)*VLOOKUP(D22,Alimentos!$A:$L,7,FALSE) -> 0.80285714 | M22: Pesar cozido; molho contabilizado à parte.
A23: Arroz branco cozido | B23: 150 | C23: Carboidrato | D23: Cuscuz de milho cozido | E23: =B23/VLOOKUP(A23,Alimentos!$A:$L,3,FALSE)*VLOOKUP(A23,Alimentos!$A:$L,IF(C23="Proteína",5,IF(C23="Carboidrato",6,7)),FALSE)/VLOOKUP(D23,Alimentos!$A:$L,IF(C23="Proteína",5,IF(C23="Carboidrato",6,7)),FALSE)*VLOOKUP(D23,Alimentos!$A:$L,3,FALSE) -> 166.60079 | F23: =VLOOKUP(D23,Alimentos!$A:$L,2,FALSE) -> g | G23: =B23/VLOOKUP(A23,Alimentos!$A:$L,3,FALSE)*VLOOKUP(A23,Alimentos!$A:$L,4,FALSE) -> 192 | H23: =E23/VLOOKUP(D23,Alimentos!$A:$L,3,FALSE)*VLOOKUP(D23,Alimentos!$A:$L,4,FALSE) -> 188.25889 | I23: =H23-G23 -> -3.7411067 | J23: =E23/VLOOKUP(D23,Alimentos!$A:$L,3,FALSE)*VLOOKUP(D23,Alimentos!$A:$L,5,FALSE) -> 3.6652174 | K23: =E23/VLOOKUP(D23,Alimentos!$A:$L,3,FALSE)*VLOOKUP(D23,Alimentos!$A:$L,6,FALSE) -> 42.15 | L23: =E23/VLOOKUP(D23,Alimentos!$A:$L,3,FALSE)*VLOOKUP(D23,Alimentos!$A:$L,7,FALSE) -> 1.1662055 | M23: Pesar cozido; manteiga contabilizada à parte.
A24: Azeite | B24: 10 | C24: Gordura | D24: Pasta de amendoim integral | E24: =B24/VLOOKUP(A24,Alimentos!$A:$L,3,FALSE)*VLOOKUP(A24,Alimentos!$A:$L,IF(C24="Proteína",5,IF(C24="Carboidrato",6,7)),FALSE)/VLOOKUP(D24,Alimentos!$A:$L,IF(C24="Proteína",5,IF(C24="Carboidrato",6,7)),FALSE)*VLOOKUP(D24,Alimentos!$A:$L,3,FALSE) -> 20 | F24: =VLOOKUP(D24,Alimentos!$A:$L,2,FALSE) -> g | G24: =B24/VLOOKUP(A24,Alimentos!$A:$L,3,FALSE)*VLOOKUP(A24,Alimentos!$A:$L,4,FALSE) -> 88.4 | H24: =E24/VLOOKUP(D24,Alimentos!$A:$L,3,FALSE)*VLOOKUP(D24,Alimentos!$A:$L,4,FALSE) -> 117.6 | I24: =H24-G24 -> 29.2 | J24: =E24/VLOOKUP(D24,Alimentos!$A:$L,3,FALSE)*VLOOKUP(D24,Alimentos!$A:$L,5,FALSE) -> 5 | K24: =E24/VLOOKUP(D24,Alimentos!$A:$L,3,FALSE)*VLOOKUP(D24,Alimentos!$A:$L,6,FALSE) -> 4 | L24: =E24/VLOOKUP(D24,Alimentos!$A:$L,3,FALSE)*VLOOKUP(D24,Alimentos!$A:$L,7,FALSE) -> 10 | M24: Atenção: adiciona 5 g de proteína e 4 g de carbo.
A25: Azeite | B25: 10 | C25: Gordura | D25: Castanha-do-pará | E25: =B25/VLOOKUP(A25,Alimentos!$A:$L,3,FALSE)*VLOOKUP(A25,Alimentos!$A:$L,IF(C25="Proteína",5,IF(C25="Carboidrato",6,7)),FALSE)/VLOOKUP(D25,Alimentos!$A:$L,IF(C25="Proteína",5,IF(C25="Carboidrato",6,7)),FALSE)*VLOOKUP(D25,Alimentos!$A:$L,3,FALSE) -> 15.748031 | F25: =VLOOKUP(D25,Alimentos!$A:$L,2,FALSE) -> g | G25: =B25/VLOOKUP(A25,Alimentos!$A:$L,3,FALSE)*VLOOKUP(A25,Alimentos!$A:$L,4,FALSE) -> 88.4 | H25: =E25/VLOOKUP(D25,Alimentos!$A:$L,3,FALSE)*VLOOKUP(D25,Alimentos!$A:$L,4,FALSE) -> 101.25984 | I25: =H25-G25 -> 12.859843 | J25: =E25/VLOOKUP(D25,Alimentos!$A:$L,3,FALSE)*VLOOKUP(D25,Alimentos!$A:$L,5,FALSE) -> 2.2834646 | K25: =E25/VLOOKUP(D25,Alimentos!$A:$L,3,FALSE)*VLOOKUP(D25,Alimentos!$A:$L,6,FALSE) -> 2.3779528 | L25: =E25/VLOOKUP(D25,Alimentos!$A:$L,3,FALSE)*VLOOKUP(D25,Alimentos!$A:$L,7,FALSE) -> 10 | M25: Aproximadamente 3 unidades médias.

Sheet Alimentação
A2: Registro diário de alimentação
A3: Consumo confirmado por você. Quantidades na unidade-base; conversão original nas observações. Sem cálculo = macros desconhecidos, nunca zero.
A5: Data | B5: Refeição | C5: Alimento | D5: Quantidade | E5: Unidade | F5: kcal | G5: Proteína g | H5: Carboidrato g | I5: Gordura g | J5: Fibra g | K5: Medição | L5: Observação | M5: Conferência | N5: ID lançamento | O5: Favorita / versão

Sheet Diário
A2: Resumo diário e metas preservadas
A5: Data | B5: Peso kg | C5: Sono h | D5: Passos | E5: Cardio min | F5: Muay Thai | G5: Registro alimentar completo | H5: Cintura cm | I5: Fome 1–5 | J5: Cansaço 1–5 | K5: Observações | L5: Meta versão | M5: Meta kcal | N5: Meta proteína | O5: Meta gordura | P5: Meta carbo | Q5: Treinos meta | R5: P mín | S5: P máx | T5: Tol kcal | U5: Tol gordura | V5: kcal | W5: Proteína g | X5: Carboidrato g | Y5: Gordura g | Z5: Fibra g | AA5: Treinos | AB5: Média peso 7d | AC5: Aderência kcal | AD5: Aderência proteína | AE5: Aderência gordura | AF5: Dias peso 7d | AG5: Itens sem cálculo
V6: =IF(A6="","",IF(COUNTIFS('Alimentação'!$A$6:$A1000,A6,'Alimentação'!$F$6:$F1000,">=0")=0,"",SUMIFS('Alimentação'!$F$6:$F1000,'Alimentação'!$A$6:$A1000,A6))) | W6: =IF(ISNUMBER(V6),SUMIFS('Alimentação'!$G:$G,'Alimentação'!$A:$A,A6),"") | X6: =IF(ISNUMBER(V6),SUMIFS('Alimentação'!$H:$H,'Alimentação'!$A:$A,A6),"") | Y6: =IF(ISNUMBER(V6),SUMIFS('Alimentação'!$I:$I,'Alimentação'!$A:$A,A6),"") | Z6: =IF(ISNUMBER(V6),SUMIFS('Alimentação'!$J:$J,'Alimentação'!$A:$A,A6),"") | AA6: =IFERROR(__xludf.DUMMYFUNCTION("IF(A6="""","""",IFERROR(COUNTUNIQUE(FILTER('Registro de treino'!$W$6:$W1000,'Registro de treino'!$A$6:$A1000=A6,'Registro de treino'!$Y$6:$Y1000=""Concluído"")),0))"),"") | AB6: =IF(OR(A6="",AF6=0),"",SUMIFS('Diário'!$B:$B,'Diário'!$A:$A,">="&A6-6,'Diário'!$A:$A,"<="&A6)/AF6) | AC6: =IF(AND(G6="Sim",AG6=0,ISNUMBER(V6),ISNUMBER(M6),M6>0),IF(ABS(V6/M6-1)<=T6,1,0),"") | AD6: =IF(AND(G6="Sim",AG6=0,ISNUMBER(W6),ISNUMBER(R6),ISNUMBER(S6)),IF(AND(W6>=R6,W6<=S6),1,0),"") | AE6: =IF(AND(G6="Sim",AG6=0,ISNUMBER(Y6),ISNUMBER(O6),O6>0),IF(ABS(Y6/O6-1)<=U6,1,0),"") | AF6: =IF(A6="","",COUNTIFS('Diário'!$A:$A,">="&A6-6,'Diário'!$A:$A,"<="&A6,'Diário'!$B:$B,">0")) | AG6: =IF(A6="","",COUNTIFS('Alimentação'!$A$6:$A1000,A6,'Alimentação'!$M$6:$M1000,"Sem cálculo"))

Sheet Semanas
A2: Evolução semanal
A5: Início | B5: Fim | C5: Pesagens | D5: Peso médio | E5: Variação kg | F5: Cintura | G5: kcal média | H5: Proteína média | I5: Gordura média | J5: Dias completos | K5: Aderência kcal | L5: Aderência proteína | M5: Treinos | N5: Meta treinos | O5: Passos médios | P5: Cardio min | Q5: Sono médio | R5: Muay Thai | S5: Situação | T5: Dias com registro | U5: Itens sem cálculo | V5: Cobertura alimentar
B6: =IF(A6="","",A6+6) | C6: =IF(A6="","",COUNTIFS('Diário'!$A:$A,">="&A6,'Diário'!$A:$A,"<="&B6,'Diário'!$B:$B,">0")) | D6: =IF(A6="","",IF(SUMPRODUCT(('Diário'!$A:$A>=A6)*('Diário'!$A:$A<=B6)*ISNUMBER('Diário'!$B:$B))=0,"",SUMIFS('Diário'!$B:$B,'Diário'!$A:$A,">="&A6,'Diário'!$A:$A,"<="&B6)/SUMPRODUCT(('Diário'!$A:$A>=A6)*('Diário'!$A:$A<=B6)*ISNUMBER('Diário'!$B:$B)))) | E6: =IF(A6="","",IF(OR(NOT(ISNUMBER(D6)),COUNTIFS(Semanas!$A:$A,A6-7,Semanas!$C:$C,">0")=0),"",D6-SUMIFS(Semanas!$D:$D,Semanas!$A:$A,A6-7))) | F6: =IF(A6="","",IF(SUMPRODUCT(('Diário'!$A:$A>=A6)*('Diário'!$A:$A<=B6)*ISNUMBER('Diário'!$H:$H))=0,"",SUMIFS('Diário'!$H:$H,'Diário'!$A:$A,">="&A6,'Diário'!$A:$A,"<="&B6)/SUMPRODUCT(('Diário'!$A:$A>=A6)*('Diário'!$A:$A<=B6)*ISNUMBER('Diário'!$H:$H)))) | G6: =IF(A6="","",IF(SUMPRODUCT(('Diário'!$A:$A>=A6)*('Diário'!$A:$A<=B6)*ISNUMBER('Diário'!$V:$V)*('Diário'!$G:$G="Sim")*('Diário'!$AG:$AG=0))=0,"",SUMIFS('Diário'!$V:$V,'Diário'!$A:$A,">="&A6,'Diário'!$A:$A,"<="&B6,'Diário'!$G:$G,"Sim",'Diário'!$AG:$AG,0)/SUMPRODUCT(('Diário'!$A:$A>=A6)*('Diário'!$A:$A<=B6)*ISNUMBER('Diário'!$V:$V)*('Diário'!$G:$G="Sim")*('Diário'!$AG:$AG=0)))) | H6: =IF(A6="","",IF(SUMPRODUCT(('Diário'!$A:$A>=A6)*('Diário'!$A:$A<=B6)*ISNUMBER('Diário'!$W:$W)*('Diário'!$G:$G="Sim")*('Diário'!$AG:$AG=0))=0,"",SUMIFS('Diário'!$W:$W,'Diário'!$A:$A,">="&A6,'Diário'!$A:$A,"<="&B6,'Diário'!$G:$G,"Sim",'Diário'!$AG:$AG,0)/SUMPRODUCT(('Diário'!$A:$A>=A6)*('Diário'!$A:$A<=B6)*ISNUMBER('Diário'!$W:$W)*('Diário'!$G:$G="Sim")*('Diário'!$AG:$AG=0)))) | I6: =IF(A6="","",IF(SUMPRODUCT(('Diário'!$A:$A>=A6)*('Diário'!$A:$A<=B6)*ISNUMBER('Diário'!$Y:$Y)*('Diário'!$G:$G="Sim")*('Diário'!$AG:$AG=0))=0,"",SUMIFS('Diário'!$Y:$Y,'Diário'!$A:$A,">="&A6,'Diário'!$A:$A,"<="&B6,'Diário'!$G:$G,"Sim",'Diário'!$AG:$AG,0)/SUMPRODUCT(('Diário'!$A:$A>=A6)*('Diário'!$A:$A<=B6)*ISNUMBER('Diário'!$Y:$Y)*('Diário'!$G:$G="Sim")*('Diário'!$AG:$AG=0)))) | J6: =IF(A6="","",COUNTIFS('Diário'!$A:$A,">="&A6,'Diário'!$A:$A,"<="&B6,'Diário'!$G:$G,"Sim",'Diário'!$V:$V,">=0",'Diário'!$AG:$AG,0)) | K6: =IF(A6="","",IF(SUMPRODUCT(('Diário'!$A:$A>=A6)*('Diário'!$A:$A<=B6)*ISNUMBER('Diário'!$AC:$AC))=0,"",SUMIFS('Diário'!$AC:$AC,'Diário'!$A:$A,">="&A6,'Diário'!$A:$A,"<="&B6)/SUMPRODUCT(('Diário'!$A:$A>=A6)*('Diário'!$A:$A<=B6)*ISNUMBER('Diário'!$AC:$AC)))) | L6: =IF(A6="","",IF(SUMPRODUCT(('Diário'!$A:$A>=A6)*('Diário'!$A:$A<=B6)*ISNUMBER('Diário'!$AD:$AD))=0,"",SUMIFS('Diário'!$AD:$AD,'Diário'!$A:$A,">="&A6,'Diário'!$A:$A,"<="&B6)/SUMPRODUCT(('Diário'!$A:$A>=A6)*('Diário'!$A:$A<=B6)*ISNUMBER('Diário'!$AD:$AD)))) | M6: =IF(A6="","",SUMIFS('Diário'!$AA:$AA,'Diário'!$A:$A,">="&A6,'Diário'!$A:$A,"<="&B6)) | N6: =IF(A6="","",IF(COUNTIFS('Diário'!$A:$A,">="&A6,'Diário'!$A:$A,"<="&B6)=0,"",SUMIFS('Diário'!$Q:$Q,'Diário'!$A:$A,">="&A6,'Diário'!$A:$A,"<="&B6)/COUNTIFS('Diário'!$A:$A,">="&A6,'Diário'!$A:$A,"<="&B6))) | O6: =IF(A6="","",IF(SUMPRODUCT(('Diário'!$A:$A>=A6)*('Diário'!$A:$A<=B6)*ISNUMBER('Diário'!$D:$D))=0,"",SUMIFS('Diário'!$D:$D,'Diário'!$A:$A,">="&A6,'Diário'!$A:$A,"<="&B6)/SUMPRODUCT(('Diário'!$A:$A>=A6)*('Diário'!$A:$A<=B6)*ISNUMBER('Diário'!$D:$D)))) | P6: =IF(A6="","",SUMIFS('Diário'!$E:$E,'Diário'!$A:$A,">="&A6,'Diário'!$A:$A,"<="&B6)) | Q6: =IF(A6="","",IF(SUMPRODUCT(('Diário'!$A:$A>=A6)*('Diário'!$A:$A<=B6)*ISNUMBER('Diário'!$C:$C))=0,"",SUMIFS('Diário'!$C:$C,'Diário'!$A:$A,">="&A6,'Diário'!$A:$A,"<="&B6)/SUMPRODUCT(('Diário'!$A:$A>=A6)*('Diário'!$A:$A<=B6)*ISNUMBER('Diário'!$C:$C)))) | R6: =IF(A6="","",COUNTIFS('Diário'!$A:$A,">="&A6,'Diário'!$A:$A,"<="&B6,'Diário'!$F:$F,"Sim")) | S6: =IF(A6="","",IF(B6>=TODAY(),"Semana parcial","Semana encerrada")) | T6: =IFERROR(__xludf.DUMMYFUNCTION("IF(A6="""","""",IFERROR(COUNTUNIQUE(FILTER('Alimentação'!$A$6:$A1000,'Alimentação'!$A$6:$A1000>=A6,'Alimentação'!$A$6:$A1000<=B6)),0))"),"") | U6: =IF(A6="","",SUMIFS('Diário'!$AG$6:$AG1000,'Diário'!$A$6:$A1000,">="&A6,'Diário'!$A$6:$A1000,"<="&B6)) | V6: =IF(A6="","",J6&" dias completos com cálculo / "&MAX(0,MIN(7,TODAY()-A6+1))&" dias decorridos")

Sheet Medidas e fotos
A2: Medidas e fotos padronizadas
A3: Cintura semanal. Outras medidas e fotos a cada 4 semanas. Mesma luz, distância e postura relaxada; fotos não medem BF com precisão.
A5: Data | B5: Cintura umbigo cm | C5: Quadril cm | D5: Peito cm | E5: Braço direito cm | F5: Coxa direita cm | G5: Frente: link | H5: Lado: link | I5: Costas: link | J5: Condições / observações

Sheet Revisões
A2: Decisões e adaptação
A3: Registrar mudanças antes de atualizar a ficha ou metas. A planilha não aumenta carga ou muda calorias automaticamente.
A5: Data | B5: Área | C5: Observação / motivo | D5: Alteração proposta | E5: Revisor | F5: Status | G5: Próxima revisão | H5: Resultado após mudança
A6: 46280.5 | B6: Ficha inicial | C6: Ficha do chat: Upper 20, Lower 16 e Full Body 19 séries após adaptação. Revisar tolerância junto ao Muay Thai. | D6: Adaptação separada em coluna própria. Não avançar automaticamente para o volume posterior. | E6: Luan | F6: A revisar
A7: 46280.5 | B7: Dieta inicial | C7: Soma das porções originais com whey e leite podia exceder a faixa proteica. | D7: Proposta atual: frango 100 g nas refeições, whey 10 g no lanche e arroz 200 g; conferir consumo real. | E7: Luan | F7: A revisar
A8: 46293 | B8: Sistema 3.0 | C8: Ambiguidade de séries, unidades e completude | D8: Work sets separadas; ficha F002; unidade explícita; correção/desfazer; favoritas pessoais | E8: Luan / atualização autorizada | F8: Aplicado
A9: 46293 | B9: Alimentação | C9: Favoritas pré-configuradas não eram individuais | D9: Favoritas e ingredientes iniciam vazios; históricos alimentares preservados vazios | E9: Luan | F9: Aplicado
A10: 28/09/2026 | B10: Automação 3.0 | C10: Parcial e retomada; conclusão explícita; sequência contínua; unidades obrigatórias; correção e desfazer; alimentos sem cálculo; Ação rápida no celular. | D10: Testes de fluxo aprovados nos dois projetos; registros temporários removidos.

Sheet Alimentos
A2: Base de alimentos e macros
A3: B e C definem a unidade e a porção-base dos nutrientes. M/N: medida caseira opcional. O: qualidade da referência. Não converter ml em g sem densidade.
